Workbook
Name DatosBio: #REF!

Sheet Taxonomy_UniqueValues
A1: Class | B1: Order | C1: Suborder | D1: Infraorder | E1: Superfamily | F1: Family | G1: Subfamily | H1: Genus | I1: Species | K1: Key
A2: #N/C | B2: #N/C | C2: #N/C | D2: =+IFERROR(IF(E2="#N/C","#N/C",INDEX('ClassificationClasses'!D:D,MATCH(E2,'ClassificationClasses'!E:E,0))),"ERROR") -> #N/C | E2: #N/C | F2: #N/C | G2: #N/C | H2: #N/C | I2: #N/C | J2: {=_xlfn.LET(_xlpm.cls,A2, _xlpm.ord,IFERROR(B2,"#N/C"), _xlpm.subord,IFERROR(C2,"#N/C"), _xlpm.infr,IFERROR(D2,"#N/C"), _xlpm.sf,IFERROR(E2,"#N/C"), _xlpm.fam,IFERROR(F2,"#N/C"), _xlpm.subfam,IF(TRIM(G2)="-","#N/C",IFERROR(G2,"#N/C")), _xlpm.subfamMatch,IFERROR(_xlfn._xlws.FILTER(ClassificationClasses[Classification Class],(ClassificationClasses[Class]=_xlpm.cls)*(ClassificationClasses[Order]=_xlpm.ord)*(ClassificationClasses[Suborder]=_xlpm.subord)*(ClassificationClasses[Infraorder]=_xlpm.infr)*(ClassificationClasses[Superfamily]=_xlpm.sf)*(ClassificationClasses[Family]=_xlpm.fam)*(ClassificationClasses[Subfamily]=_xlpm.subfam),""),""), _xlpm.uniqueSubfam,IF(_xlpm.subfamMatch="","",_xlfn.UNIQUE(_xlpm.subfamMatch)), _xlpm.numUniqueSubfam,IF(_xlpm.uniqueSubfam="",0,ROWS(_xlpm.uniqueSubfam)), _xlpm.resultSubfam,IF(_xlpm.numUniqueSubfam=1,INDEX(_xlpm.uniqueSubfam,1),IF(_xlpm.numUniqueSubfam>=1,_xlpm.subfam,"")), _xlpm.famMatch,IFERROR(_xlfn._xlws.FILTER(ClassificationClasses[Classification Class],(ClassificationClasses[Class]=_xlpm.cls)*(ClassificationClasses[Order]=_xlpm.ord)*(ClassificationClasses[Suborder]=_xlpm.subord)*(ClassificationClasses[Infraorder]=_xlpm.infr)*(ClassificationClasses[Superfamily]=_xlpm.sf)*(ClassificationClasses[Family]=_xlpm.fam),""),""), _xlpm.uniqueFam,IF(_xlpm.famMatch="","",_xlfn.UNIQUE(_xlpm.famMatch)), _xlpm.numUniqueFam,IF(_xlpm.uniqueFam="",0,ROWS(_xlpm.uniqueFam)), _xlpm.resultFam,IF(_xlpm.numUniqueFam=1,INDEX(_xlpm.uniqueFam,1),IF(_xlpm.numUniqueFam>=1,_xlpm.fam,"")), _xlpm.sfMatch,IFERROR(_xlfn._xlws.FILTER(ClassificationClasses[Classification Class],(ClassificationClasses[Class]=_xlpm.cls)*(ClassificationClasses[Order]=_xlpm.ord)*(ClassificationClasses[Suborder]=_xlpm.subord)*(ClassificationClasses[Infraorder]=_xlpm.infr)*(ClassificationClasses[Superfamily]=_xlpm.sf),""),""), _xlpm.uniqueSf,IF(_xlpm.sfMatch="","",_xlfn.UNIQUE(_xlpm.sfMatch)), _xlpm.numUniqueSf,IF(_xlpm.uniqueSf="",0,ROWS(_xlpm.uniqueSf)), _xlpm.resultSf,IF(_xlpm.numUniqueSf=1,INDEX(_xlpm.uniqueSf,1),IF(_xlpm.numUniqueSf>=1,_xlpm.sf,"")), _xlpm.computedResult,IF(AND(_xlpm.fam="#N/C",_xlpm.subfam="#N/C"),_xlpm.sf,IF(_xlpm.resultSubfam<>"",_xlpm.resultSubfam,IF(_xlpm.resultFam<>"",_xlpm.resultFam,IF(_xlpm.resultSf<>"",_xlpm.resultSf,"")))), _xlpm.fallback,IF(IFERROR(B2,"#N/C")="#N/C",A2,IF(IFERROR(C2,"#N/C")="#N/C",B2,IF(IFERROR(D2,"#N/C")="#N/C",C2,IF(IFERROR(E2,"#N/C")="#N/C",D2,IF(IFERROR(F2,"#N/C")="#N/C",E2,IF(IFERROR(G2,"#N/C")="#N/C",F2,"#N/C")))))), _xlpm.finalResult,IF(OR(_xlpm.computedResult="",_xlpm.computedResult="#N/C"),_xlpm.fallback,_xlpm.computedResult), INDEX(_xlpm.finalResult,1))} -> #N/C | K2: =+CONCATENATE(A2,".",B2,".",C2,".",D2,".",E2,".",F2,".",G2,".",H2,".",I2) -> #N/C.#N/C.#N/C.#N/C.#N/C.#N/C.#N/C.#N/C.#N/C | L2: =+COUNTIF(Monitoring!#REF!,K2) -> #REF!
A3: Arachnida | B3: Araneae | C3: Arneomorphae | D3: =+IFERROR(IF(E3="#N/C","#N/C",INDEX('ClassificationClasses'!D:D,MATCH(E3,'ClassificationClasses'!E:E,0))),"ERROR") -> Araneomorphae | E3: Araneoidea | F3: #N/C | G3: #N/C | H3: #N/C | I3: #N/C | J3: {=_xlfn.LET(_xlpm.cls,A3, _xlpm.ord,IFERROR(B3,"#N/C"), _xlpm.subord,IFERROR(C3,"#N/C"), _xlpm.infr,IFERROR(D3,"#N/C"), _xlpm.sf,IFERROR(E3,"#N/C"), _xlpm.fam,IFERROR(F3,"#N/C"), _xlpm.subfam,IF(TRIM(G3)="-","#N/C",IFERROR(G3,"#N/C")), _xlpm.subfamMatch,IFERROR(_xlfn._xlws.FILTER(ClassificationClasses[Classification Class],(ClassificationClasses[Class]=_xlpm.cls)*(ClassificationClasses[Order]=_xlpm.ord)*(ClassificationClasses[Suborder]=_xlpm.subord)*(ClassificationClasses[Infraorder]=_xlpm.infr)*(ClassificationClasses[Superfamily]=_xlpm.sf)*(ClassificationClasses[Family]=_xlpm.fam)*(ClassificationClasses[Subfamily]=_xlpm.subfam),""),""), _xlpm.uniqueSubfam,IF(_xlpm.subfamMatch="","",_xlfn.UNIQUE(_xlpm.subfamMatch)), _xlpm.numUniqueSubfam,IF(_xlpm.uniqueSubfam="",0,ROWS(_xlpm.uniqueSubfam)), _xlpm.resultSubfam,IF(_xlpm.numUniqueSubfam=1,INDEX(_xlpm.uniqueSubfam,1),IF(_xlpm.numUniqueSubfam>=1,_xlpm.subfam,"")), _xlpm.famMatch,IFERROR(_xlfn._xlws.FILTER(ClassificationClasses[Classification Class],(ClassificationClasses[Class]=_xlpm.cls)*(ClassificationClasses[Order]=_xlpm.ord)*(ClassificationClasses[Suborder]=_xlpm.subord)*(ClassificationClasses[Infraorder]=_xlpm.infr)*(ClassificationClasses[Superfamily]=_xlpm.sf)*(ClassificationClasses[Family]=_xlpm.fam),""),""), _xlpm.uniqueFam,IF(_xlpm.famMatch="","",_xlfn.UNIQUE(_xlpm.famMatch)), _xlpm.numUniqueFam,IF(_xlpm.uniqueFam="",0,ROWS(_xlpm.uniqueFam)), _xlpm.resultFam,IF(_xlpm.numUniqueFam=1,INDEX(_xlpm.uniqueFam,1),IF(_xlpm.numUniqueFam>=1,_xlpm.fam,"")), _xlpm.sfMatch,IFERROR(_xlfn._xlws.FILTER(ClassificationClasses[Classification Class],(ClassificationClasses[Class]=_xlpm.cls)*(ClassificationClasses[Order]=_xlpm.ord)*(ClassificationClasses[Suborder]=_xlpm.subord)*(ClassificationClasses[Infraorder]=_xlpm.infr)*(ClassificationClasses[Superfamily]=_xlpm.sf),""),""), _xlpm.uniqueSf,IF(_xlpm.sfMatch="","",_xlfn.UNIQUE(_xlpm.sfMatch)), _xlpm.numUniqueSf,IF(_xlpm.uniqueSf="",0,ROWS(_xlpm.uniqueSf)), _xlpm.resultSf,IF(_xlpm.numUniqueSf=1,INDEX(_xlpm.uniqueSf,1),IF(_xlpm.numUniqueSf>=1,_xlpm.sf,"")), _xlpm.computedResult,IF(AND(_xlpm.fam="#N/C",_xlpm.subfam="#N/C"),_xlpm.sf,IF(_xlpm.resultSubfam<>"",_xlpm.resultSubfam,IF(_xlpm.resultFam<>"",_xlpm.resultFam,IF(_xlpm.resultSf<>"",_xlpm.resultSf,"")))), _xlpm.fallback,IF(IFERROR(B3,"#N/C")="#N/C",A3,IF(IFERROR(C3,"#N/C")="#N/C",B3,IF(IFERROR(D3,"#N/C")="#N/C",C3,IF(IFERROR(E3,"#N/C")="#N/C",D3,IF(IFERROR(F3,"#N/C")="#N/C",E3,IF(IFERROR(G3,"#N/C")="#N/C",F3,"#N/C")))))), _xlpm.finalResult,IF(OR(_xlpm.computedResult="",_xlpm.computedResult="#N/C"),_xlpm.fallback,_xlpm.computedResult), INDEX(_xlpm.finalResult,1))} -> Araneoidea | K3: =+CONCATENATE(A3,".",B3,".",C3,".",D3,".",E3,".",F3,".",G3,".",H3,".",I3) -> Arachnida.Araneae.Arneomorphae.Araneomorphae.Araneoidea.#N/C.#N/C.#N/C.#N/C | L3: =+COUNTIF(Monitoring!#REF!,K3) -> #REF!
A4: Arachnida | B4: Araneae | C4: Arneomorphae | D4: =+IFERROR(IF(E4="#N/C","#N/C",INDEX('ClassificationClasses'!D:D,MATCH(E4,'ClassificationClasses'!E:E,0))),"ERROR") -> Araneomorphae | E4: Araneoidea | F4: Araneidae | G4: Araneinae | H4: #N/C | I4: #N/C | J4: {=_xlfn.LET(_xlpm.cls,A4, _xlpm.ord,IFERROR(B4,"#N/C"), _xlpm.subord,IFERROR(C4,"#N/C"), _xlpm.infr,IFERROR(D4,"#N/C"), _xlpm.sf,IFERROR(E4,"#N/C"), _xlpm.fam,IFERROR(F4,"#N/C"), _xlpm.subfam,IF(TRIM(G4)="-","#N/C",IFERROR(G4,"#N/C")), _xlpm.subfamMatch,IFERROR(_xlfn._xlws.FILTER(ClassificationClasses[Classification Class],(ClassificationClasses[Class]=_xlpm.cls)*(ClassificationClasses[Order]=_xlpm.ord)*(ClassificationClasses[Suborder]=_xlpm.subord)*(ClassificationClasses[Infraorder]=_xlpm.infr)*(ClassificationClasses[Superfamily]=_xlpm.sf)*(ClassificationClasses[Family]=_xlpm.fam)*(ClassificationClasses[Subfamily]=_xlpm.subfam),""),""), _xlpm.uniqueSubfam,IF(_xlpm.subfamMatch="","",_xlfn.UNIQUE(_xlpm.subfamMatch)), _xlpm.numUniqueSubfam,IF(_xlpm.uniqueSubfam="",0,ROWS(_xlpm.uniqueSubfam)), _xlpm.resultSubfam,IF(_xlpm.numUniqueSubfam=1,INDEX(_xlpm.uniqueSubfam,1),IF(_xlpm.numUniqueSubfam>=1,_xlpm.subfam,"")), _xlpm.famMatch,IFERROR(_xlfn._xlws.FILTER(ClassificationClasses[Classification Class],(ClassificationClasses[Class]=_xlpm.cls)*(ClassificationClasses[Order]=_xlpm.ord)*(ClassificationClasses[Suborder]=_xlpm.subord)*(ClassificationClasses[Infraorder]=_xlpm.infr)*(ClassificationClasses[Superfamily]=_xlpm.sf)*(ClassificationClasses[Family]=_xlpm.fam),""),""), _xlpm.uniqueFam,IF(_xlpm.famMatch="","",_xlfn.UNIQUE(_xlpm.famMatch)), _xlpm.numUniqueFam,IF(_xlpm.uniqueFam="",0,ROWS(_xlpm.uniqueFam)), _xlpm.resultFam,IF(_xlpm.numUniqueFam=1,INDEX(_xlpm.uniqueFam,1),IF(_xlpm.numUniqueFam>=1,_xlpm.fam,"")), _xlpm.sfMatch,IFERROR(_xlfn._xlws.FILTER(ClassificationClasses[Classification Class],(ClassificationClasses[Class]=_xlpm.cls)*(ClassificationClasses[Order]=_xlpm.ord)*(ClassificationClasses[Suborder]=_xlpm.subord)*(ClassificationClasses[Infraorder]=_xlpm.infr)*(ClassificationClasses[Superfamily]=_xlpm.sf),""),""), _xlpm.uniqueSf,IF(_xlpm.sfMatch="","",_xlfn.UNIQUE(_xlpm.sfMatch)), _xlpm.numUniqueSf,IF(_xlpm.uniqueSf="",0,ROWS(_xlpm.uniqueSf)), _xlpm.resultSf,IF(_xlpm.numUniqueSf=1,INDEX(_xlpm.uniqueSf,1),IF(_xlpm.numUniqueSf>=1,_xlpm.sf,"")), _xlpm.computedResult,IF(AND(_xlpm.fam="#N/C",_xlpm.subfam="#N/C"),_xlpm.sf,IF(_xlpm.resultSubfam<>"",_xlpm.resultSubfam,IF(_xlpm.resultFam<>"",_xlpm.resultFam,IF(_xlpm.resultSf<>"",_xlpm.resultSf,"")))), _xlpm.fallback,IF(IFERROR(B4,"#N/C")="#N/C",A4,IF(IFERROR(C4,"#N/C")="#N/C",B4,IF(IFERROR(D4,"#N/C")="#N/C",C4,IF(IFERROR(E4,"#N/C")="#N/C",D4,IF(IFERROR(F4,"#N/C")="#N/C",E4,IF(IFERROR(G4,"#N/C")="#N/C",F4,"#N/C")))))), _xlpm.finalResult,IF(OR(_xlpm.computedResult="",_xlpm.computedResult="#N/C"),_xlpm.fallback,_xlpm.computedResult), INDEX(_xlpm.finalResult,1))} -> spider | K4: =+CONCATENATE(A4,".",B4,".",C4,".",D4,".",E4,".",F4,".",G4,".",H4,".",I4) -> Arachnida.Araneae.Arneomorphae.Araneomorphae.Araneoidea.Araneidae.Araneinae.#N/C.#N/C | L4: =+COUNTIF(Monitoring!#REF!,K4) -> #REF!
A5: Arachnida | B5: Araneae | C5: Arneomorphae | D5: =+IFERROR(IF(E5="#N/C","#N/C",INDEX('ClassificationClasses'!D:D,MATCH(E5,'ClassificationClasses'!E:E,0))),"ERROR") -> Araneomorphae | E5: Araneoidea | F5: Araneidae | G5: Araneinae | H5: Araneus | I5: #N/C | J5: {=_xlfn.LET(_xlpm.cls,A5, _xlpm.ord,IFERROR(B5,"#N/C"), _xlpm.subord,IFERROR(C5,"#N/C"), _xlpm.infr,IFERROR(D5,"#N/C"), _xlpm.sf,IFERROR(E5,"#N/C"), _xlpm.fam,IFERROR(F5,"#N/C"), _xlpm.subfam,IF(TRIM(G5)="-","#N/C",IFERROR(G5,"#N/C")), _xlpm.subfamMatch,IFERROR(_xlfn._xlws.FILTER(ClassificationClasses[Classification Class],(ClassificationClasses[Class]=_xlpm.cls)*(ClassificationClasses[Order]=_xlpm.ord)*(ClassificationClasses[Suborder]=_xlpm.subord)*(ClassificationClasses[Infraorder]=_xlpm.infr)*(ClassificationClasses[Superfamily]=_xlpm.sf)*(ClassificationClasses[Family]=_xlpm.fam)*(ClassificationClasses[Subfamily]=_xlpm.subfam),""),""), _xlpm.uniqueSubfam,IF(_xlpm.subfamMatch="","",_xlfn.UNIQUE(_xlpm.subfamMatch)), _xlpm.numUniqueSubfam,IF(_xlpm.uniqueSubfam="",0,ROWS(_xlpm.uniqueSubfam)), _xlpm.resultSubfam,IF(_xlpm.numUniqueSubfam=1,INDEX(_xlpm.uniqueSubfam,1),IF(_xlpm.numUniqueSubfam>=1,_xlpm.subfam,"")), _xlpm.famMatch,IFERROR(_xlfn._xlws.FILTER(ClassificationClasses[Classification Class],(ClassificationClasses[Class]=_xlpm.cls)*(ClassificationClasses[Order]=_xlpm.ord)*(ClassificationClasses[Suborder]=_xlpm.subord)*(ClassificationClasses[Infraorder]=_xlpm.infr)*(ClassificationClasses[Superfamily]=_xlpm.sf)*(ClassificationClasses[Family]=_xlpm.fam),""),""), _xlpm.uniqueFam,IF(_xlpm.famMatch="","",_xlfn.UNIQUE(_xlpm.famMatch)), _xlpm.numUniqueFam,IF(_xlpm.uniqueFam="",0,ROWS(_xlpm.uniqueFam)), _xlpm.resultFam,IF(_xlpm.numUniqueFam=1,INDEX(_xlpm.uniqueFam,1),IF(_xlpm.numUniqueFam>=1,_xlpm.fam,"")), _xlpm.sfMatch,IFERROR(_xlfn._xlws.FILTER(ClassificationClasses[Classification Class],(ClassificationClasses[Class]=_xlpm.cls)*(ClassificationClasses[Order]=_xlpm.ord)*(ClassificationClasses[Suborder]=_xlpm.subord)*(ClassificationClasses[Infraorder]=_xlpm.infr)*(ClassificationClasses[Superfamily]=_xlpm.sf),""),""), _xlpm.uniqueSf,IF(_xlpm.sfMatch="","",_xlfn.UNIQUE(_xlpm.sfMatch)), _xlpm.numUniqueSf,IF(_xlpm.uniqueSf="",0,ROWS(_xlpm.uniqueSf)), _xlpm.resultSf,IF(_xlpm.numUniqueSf=1,INDEX(_xlpm.uniqueSf,1),IF(_xlpm.numUniqueSf>=1,_xlpm.sf,"")), _xlpm.computedResult,IF(AND(_xlpm.fam="#N/C",_xlpm.subfam="#N/C"),_xlpm.sf,IF(_xlpm.resultSubfam<>"",_xlpm.resultSubfam,IF(_xlpm.resultFam<>"",_xlpm.resultFam,IF(_xlpm.resultSf<>"",_xlpm.resultSf,"")))), _xlpm.fallback,IF(IFERROR(B5,"#N/C")="#N/C",A5,IF(IFERROR(C5,"#N/C")="#N/C",B5,IF(IFERROR(D5,"#N/C")="#N/C",C5,IF(IFERROR(E5,"#N/C")="#N/C",D5,IF(IFERROR(F5,"#N/C")="#N/C",E5,IF(IFERROR(G5,"#N/C")="#N/C",F5,"#N/C")))))), _xlpm.finalResult,IF(OR(_xlpm.computedResult="",_xlpm.computedResult="#N/C"),_xlpm.fallback,_xlpm.computedResult), INDEX(_xlpm.finalResult,1))} -> spider | K5: =+CONCATENATE(A5,".",B5,".",C5,".",D5,".",E5,".",F5,".",G5,".",H5,".",I5) -> Arachnida.Araneae.Arneomorphae.Araneomorphae.Araneoidea.Araneidae.Araneinae.Araneus.#N/C | L5: =+COUNTIF(Monitoring!#REF!,K5) -> #REF!
A6: Arachnida | B6: Araneae | C6: Arneomorphae | D6: =+IFERROR(IF(E6="#N/C","#N/C",INDEX('ClassificationClasses'!D:D,MATCH(E6,'ClassificationClasses'!E:E,0))),"ERROR") -> Araneomorphae | E6: Dictynoidea | F6: Anyphaenidae | G6: Anyphaeninae | H6: Anyphaena | I6: #N/C | J6: {=_xlfn.LET(_xlpm.cls,A6, _xlpm.ord,IFERROR(B6,"#N/C"), _xlpm.subord,IFERROR(C6,"#N/C"), _xlpm.infr,IFERROR(D6,"#N/C"), _xlpm.sf,IFERROR(E6,"#N/C"), _xlpm.fam,IFERROR(F6,"#N/C"), _xlpm.subfam,IF(TRIM(G6)="-","#N/C",IFERROR(G6,"#N/C")), _xlpm.subfamMatch,IFERROR(_xlfn._xlws.FILTER(ClassificationClasses[Classification Class],(ClassificationClasses[Class]=_xlpm.cls)*(ClassificationClasses[Order]=_xlpm.ord)*(ClassificationClasses[Suborder]=_xlpm.subord)*(ClassificationClasses[Infraorder]=_xlpm.infr)*(ClassificationClasses[Superfamily]=_xlpm.sf)*(ClassificationClasses[Family]=_xlpm.fam)*(ClassificationClasses[Subfamily]=_xlpm.subfam),""),""), _xlpm.uniqueSubfam,IF(_xlpm.subfamMatch="","",_xlfn.UNIQUE(_xlpm.subfamMatch)), _xlpm.numUniqueSubfam,IF(_xlpm.uniqueSubfam="",0,ROWS(_xlpm.uniqueSubfam)), _xlpm.resultSubfam,IF(_xlpm.numUniqueSubfam=1,INDEX(_xlpm.uniqueSubfam,1),IF(_xlpm.numUniqueSubfam>=1,_xlpm.subfam,"")), _xlpm.famMatch,IFERROR(_xlfn._xlws.FILTER(ClassificationClasses[Classification Class],(ClassificationClasses[Class]=_xlpm.cls)*(ClassificationClasses[Order]=_xlpm.ord)*(ClassificationClasses[Suborder]=_xlpm.subord)*(ClassificationClasses[Infraorder]=_xlpm.infr)*(ClassificationClasses[Superfamily]=_xlpm.sf)*(ClassificationClasses[Family]=_xlpm.fam),""),""), _xlpm.uniqueFam,IF(_xlpm.famMatch="","",_xlfn.UNIQUE(_xlpm.famMatch)), _xlpm.numUniqueFam,IF(_xlpm.uniqueFam="",0,ROWS(_xlpm.uniqueFam)), _xlpm.resultFam,IF(_xlpm.numUniqueFam=1,INDEX(_xlpm.uniqueFam,1),IF(_xlpm.numUniqueFam>=1,_xlpm.fam,"")), _xlpm.sfMatch,IFERROR(_xlfn._xlws.FILTER(ClassificationClasses[Classification Class],(ClassificationClasses[Class]=_xlpm.cls)*(ClassificationClasses[Order]=_xlpm.ord)*(ClassificationClasses[Suborder]=_xlpm.subord)*(ClassificationClasses[Infraorder]=_xlpm.infr)*(ClassificationClasses[Superfamily]=_xlpm.sf),""),""), _xlpm.uniqueSf,IF(_xlpm.sfMatch="","",_xlfn.UNIQUE(_xlpm.sfMatch)), _xlpm.numUniqueSf,IF(_xlpm.uniqueSf="",0,ROWS(_xlpm.uniqueSf)), _xlpm.resultSf,IF(_xlpm.numUniqueSf=1,INDEX(_xlpm.uniqueSf,1),IF(_xlpm.numUniqueSf>=1,_xlpm.sf,"")), _xlpm.computedResult,IF(AND(_xlpm.fam="#N/C",_xlpm.subfam="#N/C"),_xlpm.sf,IF(_xlpm.resultSubfam<>"",_xlpm.resultSubfam,IF(_xlpm.resultFam<>"",_xlpm.resultFam,IF(_xlpm.resultSf<>"",_xlpm.resultSf,"")))), _xlpm.fallback,IF(IFERROR(B6,"#N/C")="#N/C",A6,IF(IFERROR(C6,"#N/C")="#N/C",B6,IF(IFERROR(D6,"#N/C")="#N/C",C6,IF(IFERROR(E6,"#N/C")="#N/C",D6,IF(IFERROR(F6,"#N/C")="#N/C",E6,IF(IFERROR(G6,"#N/C")="#N/C",F6,"#N/C")))))), _xlpm.finalResult,IF(OR(_xlpm.computedResult="",_xlpm.computedResult="#N/C"),_xlpm.fallback,_xlpm.computedResult), INDEX(_xlpm.finalResult,1))} -> spider | K6: =+CONCATENATE(A6,".",B6,".",C6,".",D6,".",E6,".",F6,".",G6,".",H6,".",I6) -> Arachnida.Araneae.Arneomorphae.Araneomorphae.Dictynoidea.Anyphaenidae.Anyphaeninae.Anyphaena.#N/C | L6: =+COUNTIF(Monitoring!#REF!,K6) -> #REF!
A7: Insecta | B7: #N/C | C7: #N/C | D7: =+IFERROR(IF(E7="#N/C","#N/C",INDEX('ClassificationClasses'!D:D,MATCH(E7,'ClassificationClasses'!E:E,0))),"ERROR") -> #N/C | E7: #N/C | F7: #N/C | G7: #N/C | H7: #N/C | I7: #N/C | J7: {=_xlfn.LET(_xlpm.cls,A7, _xlpm.ord,IFERROR(B7,"#N/C"), _xlpm.subord,IFERROR(C7,"#N/C"), _xlpm.infr,IFERROR(D7,"#N/C"), _xlpm.sf,IFERROR(E7,"#N/C"), _xlpm.fam,IFERROR(F7,"#N/C"), _xlpm.subfam,IF(TRIM(G7)="-","#N/C",IFERROR(G7,"#N/C")), _xlpm.subfamMatch,IFERROR(_xlfn._xlws.FILTER(ClassificationClasses[Classification Class],(ClassificationClasses[Class]=_xlpm.cls)*(ClassificationClasses[Order]=_xlpm.ord)*(ClassificationClasses[Suborder]=_xlpm.subord)*(ClassificationClasses[Infraorder]=_xlpm.infr)*(ClassificationClasses[Superfamily]=_xlpm.sf)*(ClassificationClasses[Family]=_xlpm.fam)*(ClassificationClasses[Subfamily]=_xlpm.subfam),""),""), _xlpm.uniqueSubfam,IF(_xlpm.subfamMatch="","",_xlfn.UNIQUE(_xlpm.subfamMatch)), _xlpm.numUniqueSubfam,IF(_xlpm.uniqueSubfam="",0,ROWS(_xlpm.uniqueSubfam)), _xlpm.resultSubfam,IF(_xlpm.numUniqueSubfam=1,INDEX(_xlpm.uniqueSubfam,1),IF(_xlpm.numUniqueSubfam>=1,_xlpm.subfam,"")), _xlpm.famMatch,IFERROR(_xlfn._xlws.FILTER(ClassificationClasses[Classification Class],(ClassificationClasses[Class]=_xlpm.cls)*(ClassificationClasses[Order]=_xlpm.ord)*(ClassificationClasses[Suborder]=_xlpm.subord)*(ClassificationClasses[Infraorder]=_xlpm.infr)*(ClassificationClasses[Superfamily]=_xlpm.sf)*(ClassificationClasses[Family]=_xlpm.fam),""),""), _xlpm.uniqueFam,IF(_xlpm.famMatch="","",_xlfn.UNIQUE(_xlpm.famMatch)), _xlpm.numUniqueFam,IF(_xlpm.uniqueFam="",0,ROWS(_xlpm.uniqueFam)), _xlpm.resultFam,IF(_xlpm.numUniqueFam=1,INDEX(_xlpm.uniqueFam,1),IF(_xlpm.numUniqueFam>=1,_xlpm.fam,"")), _xlpm.sfMatch,IFERROR(_xlfn._xlws.FILTER(ClassificationClasses[Classification Class],(ClassificationClasses[Class]=_xlpm.cls)*(ClassificationClasses[Order]=_xlpm.ord)*(ClassificationClasses[Suborder]=_xlpm.subord)*(ClassificationClasses[Infraorder]=_xlpm.infr)*(ClassificationClasses[Superfamily]=_xlpm.sf),""),""), _xlpm.uniqueSf,IF(_xlpm.sfMatch="","",_xlfn.UNIQUE(_xlpm.sfMatch)), _xlpm.numUniqueSf,IF(_xlpm.uniqueSf="",0,ROWS(_xlpm.uniqueSf)), _xlpm.resultSf,IF(_xlpm.numUniqueSf=1,INDEX(_xlpm.uniqueSf,1),IF(_xlpm.numUniqueSf>=1,_xlpm.sf,"")), _xlpm.computedResult,IF(AND(_xlpm.fam="#N/C",_xlpm.subfam="#N/C"),_xlpm.sf,IF(_xlpm.resultSubfam<>"",_xlpm.resultSubfam,IF(_xlpm.resultFam<>"",_xlpm.resultFam,IF(_xlpm.resultSf<>"",_xlpm.resultSf,"")))), _xlpm.fallback,IF(IFERROR(B7,"#N/C")="#N/C",A7,IF(IFERROR(C7,"#N/C")="#N/C",B7,IF(IFERROR(D7,"#N/C")="#N/C",C7,IF(IFERROR(E7,"#N/C")="#N/C",D7,IF(IFERROR(F7,"#N/C")="#N/C",E7,IF(IFERROR(G7,"#N/C")="#N/C",F7,"#N/C")))))), _xlpm.finalResult,IF(OR(_xlpm.computedResult="",_xlpm.computedResult="#N/C"),_xlpm.fallback,_xlpm.computedResult), INDEX(_xlpm.finalResult,1))} -> Insecta | K7: =+CONCATENATE(A7,".",B7,".",C7,".",D7,".",E7,".",F7,".",G7,".",H7,".",I7) -> Insecta.#N/C.#N/C.#N/C.#N/C.#N/C.#N/C.#N/C.#N/C | L7: =+COUNTIF(Monitoring!#REF!,K7) -> #REF!
A8: Insecta | B8: Coleoptera | C8: Polyphaga | D8: =+IFERROR(IF(E8="#N/C","#N/C",INDEX('ClassificationClasses'!D:D,MATCH(E8,'ClassificationClasses'!E:E,0))),"ERROR") -> Cucujiformia | E8: Chrysomeloidea | F8: Chrysomelidae | G8: Alticinae | H8: #N/C | I8: #N/C | J8: {=_xlfn.LET(_xlpm.cls,A8, _xlpm.ord,IFERROR(B8,"#N/C"), _xlpm.subord,IFERROR(C8,"#N/C"), _xlpm.infr,IFERROR(D8,"#N/C"), _xlpm.sf,IFERROR(E8,"#N/C"), _xlpm.fam,IFERROR(F8,"#N/C"), _xlpm.subfam,IF(TRIM(G8)="-","#N/C",IFERROR(G8,"#N/C")), _xlpm.subfamMatch,IFERROR(_xlfn._xlws.FILTER(ClassificationClasses[Classification Class],(ClassificationClasses[Class]=_xlpm.cls)*(ClassificationClasses[Order]=_xlpm.ord)*(ClassificationClasses[Suborder]=_xlpm.subord)*(ClassificationClasses[Infraorder]=_xlpm.infr)*(ClassificationClasses[Superfamily]=_xlpm.sf)*(ClassificationClasses[Family]=_xlpm.fam)*(ClassificationClasses[Subfamily]=_xlpm.subfam),""),""), _xlpm.uniqueSubfam,IF(_xlpm.subfamMatch="","",_xlfn.UNIQUE(_xlpm.subfamMatch)), _xlpm.numUniqueSubfam,IF(_xlpm.uniqueSubfam="",0,ROWS(_xlpm.uniqueSubfam)), _xlpm.resultSubfam,IF(_xlpm.numUniqueSubfam=1,INDEX(_xlpm.uniqueSubfam,1),IF(_xlpm.numUniqueSubfam>=1,_xlpm.subfam,"")), _xlpm.famMatch,IFERROR(_xlfn._xlws.FILTER(ClassificationClasses[Classification Class],(ClassificationClasses[Class]=_xlpm.cls)*(ClassificationClasses[Order]=_xlpm.ord)*(ClassificationClasses[Suborder]=_xlpm.subord)*(ClassificationClasses[Infraorder]=_xlpm.infr)*(ClassificationClasses[Superfamily]=_xlpm.sf)*(ClassificationClasses[Family]=_xlpm.fam),""),""), _xlpm.uniqueFam,IF(_xlpm.famMatch="","",_xlfn.UNIQUE(_xlpm.famMatch)), _xlpm.numUniqueFam,IF(_xlpm.uniqueFam="",0,ROWS(_xlpm.uniqueFam)), _xlpm.resultFam,IF(_xlpm.numUniqueFam=1,INDEX(_xlpm.uniqueFam,1),IF(_xlpm.numUniqueFam>=1,_xlpm.fam,"")), _xlpm.sfMatch,IFERROR(_xlfn._xlws.FILTER(ClassificationClasses[Classification Class],(ClassificationClasses[Class]=_xlpm.cls)*(ClassificationClasses[Order]=_xlpm.ord)*(ClassificationClasses[Suborder]=_xlpm.subord)*(ClassificationClasses[Infraorder]=_xlpm.infr)*(ClassificationClasses[Superfamily]=_xlpm.sf),""),""), _xlpm.uniqueSf,IF(_xlpm.sfMatch="","",_xlfn.UNIQUE(_xlpm.sfMatch)), _xlpm.numUniqueSf,IF(_xlpm.uniqueSf="",0,ROWS(_xlpm.uniqueSf)), _xlpm.resultSf,IF(_xlpm.numUniqueSf=1,INDEX(_xlpm.uniqueSf,1),IF(_xlpm.numUniqueSf>=1,_xlpm.sf,"")), _xlpm.computedResult,IF(AND(_xlpm.fam="#N/C",_xlpm.subfam="#N/C"),_xlpm.sf,IF(_xlpm.resultSubfam<>"",_xlpm.resultSubfam,IF(_xlpm.resultFam<>"",_xlpm.resultFam,IF(_xlpm.resultSf<>"",_xlpm.resultSf,"")))), _xlpm.fallback,IF(IFERROR(B8,"#N/C")="#N/C",A8,IF(IFERROR(C8,"#N/C")="#N/C",B8,IF(IFERROR(D8,"#N/C")="#N/C",C8,IF(IFERROR(E8,"#N/C")="#N/C",D8,IF(IFERROR(F8,"#N/C")="#N/C",E8,IF(IFERROR(G8,"#N/C")="#N/C",F8,"#N/C")))))), _xlpm.finalResult,IF(OR(_xlpm.computedResult="",_xlpm.computedResult="#N/C"),_xlpm.fallback,_xlpm.computedResult), INDEX(_xlpm.finalResult,1))} -> leaf_beetle | K8: =+CONCATENATE(A8,".",B8,".",C8,".",D8,".",E8,".",F8,".",G8,".",H8,".",I8) -> Insecta.Coleoptera.Polyphaga.Cucujiformia.Chrysomeloidea.Chrysomelidae.Alticinae.#N/C.#N/C | L8: =+COUNTIF(Monitoring!#REF!,K8) -> #REF!
A9: Insecta | B9: Coleoptera | C9: Polyphaga | D9: =+IFERROR(IF(E9="#N/C","#N/C",INDEX('ClassificationClasses'!D:D,MATCH(E9,'ClassificationClasses'!E:E,0))),"ERROR") -> Cucujiformia | E9: Chrysomeloidea | F9: Chrysomelidae | G9: Chrysomelinae | H9: #N/C | I9: #N/C | J9: {=_xlfn.LET(_xlpm.cls,A9, _xlpm.ord,IFERROR(B9,"#N/C"), _xlpm.subord,IFERROR(C9,"#N/C"), _xlpm.infr,IFERROR(D9,"#N/C"), _xlpm.sf,IFERROR(E9,"#N/C"), _xlpm.fam,IFERROR(F9,"#N/C"), _xlpm.subfam,IF(TRIM(G9)="-","#N/C",IFERROR(G9,"#N/C")), _xlpm.subfamMatch,IFERROR(_xlfn._xlws.FILTER(ClassificationClasses[Classification Class],(ClassificationClasses[Class]=_xlpm.cls)*(ClassificationClasses[Order]=_xlpm.ord)*(ClassificationClasses[Suborder]=_xlpm.subord)*(ClassificationClasses[Infraorder]=_xlpm.infr)*(ClassificationClasses[Superfamily]=_xlpm.sf)*(ClassificationClasses[Family]=_xlpm.fam)*(ClassificationClasses[Subfamily]=_xlpm.subfam),""),""), _xlpm.uniqueSubfam,IF(_xlpm.subfamMatch="","",_xlfn.UNIQUE(_xlpm.subfamMatch)), _xlpm.numUniqueSubfam,IF(_xlpm.uniqueSubfam="",0,ROWS(_xlpm.uniqueSubfam)), _xlpm.resultSubfam,IF(_xlpm.numUniqueSubfam=1,INDEX(_xlpm.uniqueSubfam,1),IF(_xlpm.numUniqueSubfam>=1,_xlpm.subfam,"")), _xlpm.famMatch,IFERROR(_xlfn._xlws.FILTER(ClassificationClasses[Classification Class],(ClassificationClasses[Class]=_xlpm.cls)*(ClassificationClasses[Order]=_xlpm.ord)*(ClassificationClasses[Suborder]=_xlpm.subord)*(ClassificationClasses[Infraorder]=_xlpm.infr)*(ClassificationClasses[Superfamily]=_xlpm.sf)*(ClassificationClasses[Family]=_xlpm.fam),""),""), _xlpm.uniqueFam,IF(_xlpm.famMatch="","",_xlfn.UNIQUE(_xlpm.famMatch)), _xlpm.numUniqueFam,IF(_xlpm.uniqueFam="",0,ROWS(_xlpm.uniqueFam)), _xlpm.resultFam,IF(_xlpm.numUniqueFam=1,INDEX(_xlpm.uniqueFam,1),IF(_xlpm.numUniqueFam>=1,_xlpm.fam,"")), _xlpm.sfMatch,IFERROR(_xlfn._xlws.FILTER(ClassificationClasses[Classification Class],(ClassificationClasses[Class]=_xlpm.cls)*(ClassificationClasses[Order]=_xlpm.ord)*(ClassificationClasses[Suborder]=_xlpm.subord)*(ClassificationClasses[Infraorder]=_xlpm.infr)*(ClassificationClasses[Superfamily]=_xlpm.sf),""),""), _xlpm.uniqueSf,IF(_xlpm.sfMatch="","",_xlfn.UNIQUE(_xlpm.sfMatch)), _xlpm.numUniqueSf,IF(_xlpm.uniqueSf="",0,ROWS(_xlpm.uniqueSf)), _xlpm.resultSf,IF(_xlpm.numUniqueSf=1,INDEX(_xlpm.uniqueSf,1),IF(_xlpm.numUniqueSf>=1,_xlpm.sf,"")), _xlpm.computedResult,IF(AND(_xlpm.fam="#N/C",_xlpm.subfam="#N/C"),_xlpm.sf,IF(_xlpm.resultSubfam<>"",_xlpm.resultSubfam,IF(_xlpm.resultFam<>"",_xlpm.resultFam,IF(_xlpm.resultSf<>"",_xlpm.resultSf,"")))), _xlpm.fallback,IF(IFERROR(B9,"#N/C")="#N/C",A9,IF(IFERROR(C9,"#N/C")="#N/C",B9,IF(IFERROR(D9,"#N/C")="#N/C",C9,IF(IFERROR(E9,"#N/C")="#N/C",D9,IF(IFERROR(F9,"#N/C")="#N/C",E9,IF(IFERROR(G9,"#N/C")="#N/C",F9,"#N/C")))))), _xlpm.finalResult,IF(OR(_xlpm.computedResult="",_xlpm.computedResult="#N/C"),_xlpm.fallback,_xlpm.computedResult), INDEX(_xlpm.finalResult,1))} -> leaf_beetle | K9: =+CONCATENATE(A9,".",B9,".",C9,".",D9,".",E9,".",F9,".",G9,".",H9,".",I9) -> Insecta.Coleoptera.Polyphaga.Cucujiformia.Chrysomeloidea.Chrysomelidae.Chrysomelinae.#N/C.#N/C | L9: =+COUNTIF(Monitoring!#REF!,K9) -> #REF!
A10: Insecta | B10: Coleoptera | C10: Polyphaga | D10: =+IFERROR(IF(E10="#N/C","#N/C",INDEX('ClassificationClasses'!D:D,MATCH(E10,'ClassificationClasses'!E:E,0))),"ERROR") -> Cucujiformia | E10: Chrysomeloidea | F10: Chrysomelidae | G10: Chrysomelinae | H10: Chrysolina | I10: #N/C | J10: {=_xlfn.LET(_xlpm.cls,A10, _xlpm.ord,IFERROR(B10,"#N/C"), _xlpm.subord,IFERROR(C10,"#N/C"), _xlpm.infr,IFERROR(D10,"#N/C"), _xlpm.sf,IFERROR(E10,"#N/C"), _xlpm.fam,IFERROR(F10,"#N/C"), _xlpm.subfam,IF(TRIM(G10)="-","#N/C",IFERROR(G10,"#N/C")), _xlpm.subfamMatch,IFERROR(_xlfn._xlws.FILTER(ClassificationClasses[Classification Class],(ClassificationClasses[Class]=_xlpm.cls)*(ClassificationClasses[Order]=_xlpm.ord)*(ClassificationClasses[Suborder]=_xlpm.subord)*(ClassificationClasses[Infraorder]=_xlpm.infr)*(ClassificationClasses[Superfamily]=_xlpm.sf)*(ClassificationClasses[Family]=_xlpm.fam)*(ClassificationClasses[Subfamily]=_xlpm.subfam),""),""), _xlpm.uniqueSubfam,IF(_xlpm.subfamMatch="","",_xlfn.UNIQUE(_xlpm.subfamMatch)), _xlpm.numUniqueSubfam,IF(_xlpm.uniqueSubfam="",0,ROWS(_xlpm.uniqueSubfam)), _xlpm.resultSubfam,IF(_xlpm.numUniqueSubfam=1,INDEX(_xlpm.uniqueSubfam,1),IF(_xlpm.numUniqueSubfam>=1,_xlpm.subfam,"")), _xlpm.famMatch,IFERROR(_xlfn._xlws.FILTER(ClassificationClasses[Classification Class],(ClassificationClasses[Class]=_xlpm.cls)*(ClassificationClasses[Order]=_xlpm.ord)*(ClassificationClasses[Suborder]=_xlpm.subord)*(ClassificationClasses[Infraorder]=_xlpm.infr)*(ClassificationClasses[Superfamily]=_xlpm.sf)*(ClassificationClasses[Family]=_xlpm.fam),""),""), _xlpm.uniqueFam,IF(_xlpm.famMatch="","",_xlfn.UNIQUE(_xlpm.famMatch)), _xlpm.numUniqueFam,IF(_xlpm.uniqueFam="",0,ROWS(_xlpm.uniqueFam)), _xlpm.resultFam,IF(_xlpm.numUniqueFam=1,INDEX(_xlpm.uniqueFam,1),IF(_xlpm.numUniqueFam>=1,_xlpm.fam,"")), _xlpm.sfMatch,IFERROR(_xlfn._xlws.FILTER(ClassificationClasses[Classification Class],(ClassificationClasses[Class]=_xlpm.cls)*(ClassificationClasses[Order]=_xlpm.ord)*(ClassificationClasses[Suborder]=_xlpm.subord)*(ClassificationClasses[Infraorder]=_xlpm.infr)*(ClassificationClasses[Superfamily]=_xlpm.sf),""),""), _xlpm.uniqueSf,IF(_xlpm.sfMatch="","",_xlfn.UNIQUE(_xlpm.sfMatch)), _xlpm.numUniqueSf,IF(_xlpm.uniqueSf="",0,ROWS(_xlpm.uniqueSf)), _xlpm.resultSf,IF(_xlpm.numUniqueSf=1,INDEX(_xlpm.uniqueSf,1),IF(_xlpm.numUniqueSf>=1,_xlpm.sf,"")), _xlpm.computedResult,IF(AND(_xlpm.fam="#N/C",_xlpm.subfam="#N/C"),_xlpm.sf,IF(_xlpm.resultSubfam<>"",_xlpm.resultSubfam,IF(_xlpm.resultFam<>"",_xlpm.resultFam,IF(_xlpm.resultSf<>"",_xlpm.resultSf,"")))), _xlpm.fallback,IF(IFERROR(B10,"#N/C")="#N/C",A10,IF(IFERROR(C10,"#N/C")="#N/C",B10,IF(IFERROR(D10,"#N/C")="#N/C",C10,IF(IFERROR(E10,"#N/C")="#N/C",D10,IF(IFERROR(F10,"#N/C")="#N/C",E10,IF(IFERROR(G10,"#N/C")="#N/C",F10,"#N/C")))))), _xlpm.finalResult,IF(OR(_xlpm.computedResult="",_xlpm.computedResult="#N/C"),_xlpm.fallback,_xlpm.computedResult), INDEX(_xlpm.finalResult,1))} -> leaf_beetle | K10: =+CONCATENATE(A10,".",B10,".",C10,".",D10,".",E10,".",F10,".",G10,".",H10,".",I10) -> Insecta.Coleoptera.Polyphaga.Cucujiformia.Chrysomeloidea.Chrysomelidae.Chrysomelinae.Chrysolina.#N/C | L10: =+COUNTIF(Monitoring!#REF!,K10) -> #REF!
A11: Insecta | B11: Coleoptera | C11: Polyphaga | D11: =+IFERROR(IF(E11="#N/C","#N/C",INDEX('ClassificationClasses'!D:D,MATCH(E11,'ClassificationClasses'!E:E,0))),"ERROR") -> Cucujiformia | E11: Chrysomeloidea | F11: Chrysomelidae | G11: Criocerinae | H11: Oulema | I11: #N/C | J11: {=_xlfn.LET(_xlpm.cls,A11, _xlpm.ord,IFERROR(B11,"#N/C"), _xlpm.subord,IFERROR(C11,"#N/C"), _xlpm.infr,IFERROR(D11,"#N/C"), _xlpm.sf,IFERROR(E11,"#N/C"), _xlpm.fam,IFERROR(F11,"#N/C"), _xlpm.subfam,IF(TRIM(G11)="-","#N/C",IFERROR(G11,"#N/C")), _xlpm.subfamMatch,IFERROR(_xlfn._xlws.FILTER(ClassificationClasses[Classification Class],(ClassificationClasses[Class]=_xlpm.cls)*(ClassificationClasses[Order]=_xlpm.ord)*(ClassificationClasses[Suborder]=_xlpm.subord)*(ClassificationClasses[Infraorder]=_xlpm.infr)*(ClassificationClasses[Superfamily]=_xlpm.sf)*(ClassificationClasses[Family]=_xlpm.fam)*(ClassificationClasses[Subfamily]=_xlpm.subfam),""),""), _xlpm.uniqueSubfam,IF(_xlpm.subfamMatch="","",_xlfn.UNIQUE(_xlpm.subfamMatch)), _xlpm.numUniqueSubfam,IF(_xlpm.uniqueSubfam="",0,ROWS(_xlpm.uniqueSubfam)), _xlpm.resultSubfam,IF(_xlpm.numUniqueSubfam=1,INDEX(_xlpm.uniqueSubfam,1),IF(_xlpm.numUniqueSubfam>=1,_xlpm.subfam,"")), _xlpm.famMatch,IFERROR(_xlfn._xlws.FILTER(ClassificationClasses[Classification Class],(ClassificationClasses[Class]=_xlpm.cls)*(ClassificationClasses[Order]=_xlpm.ord)*(ClassificationClasses[Suborder]=_xlpm.subord)*(ClassificationClasses[Infraorder]=_xlpm.infr)*(ClassificationClasses[Superfamily]=_xlpm.sf)*(ClassificationClasses[Family]=_xlpm.fam),""),""), _xlpm.uniqueFam,IF(_xlpm.famMatch="","",_xlfn.UNIQUE(_xlpm.famMatch)), _xlpm.numUniqueFam,IF(_xlpm.uniqueFam="",0,ROWS(_xlpm.uniqueFam)), _xlpm.resultFam,IF(_xlpm.numUniqueFam=1,INDEX(_xlpm.uniqueFam,1),IF(_xlpm.numUniqueFam>=1,_xlpm.fam,"")), _xlpm.sfMatch,IFERROR(_xlfn._xlws.FILTER(ClassificationClasses[Classification Class],(ClassificationClasses[Class]=_xlpm.cls)*(ClassificationClasses[Order]=_xlpm.ord)*(ClassificationClasses[Suborder]=_xlpm.subord)*(ClassificationClasses[Infraorder]=_xlpm.infr)*(ClassificationClasses[Superfamily]=_xlpm.sf),""),""), _xlpm.uniqueSf,IF(_xlpm.sfMatch="","",_xlfn.UNIQUE(_xlpm.sfMatch)), _xlpm.numUniqueSf,IF(_xlpm.uniqueSf="",0,ROWS(_xlpm.uniqueSf)), _xlpm.resultSf,IF(_xlpm.numUniqueSf=1,INDEX(_xlpm.uniqueSf,1),IF(_xlpm.numUniqueSf>=1,_xlpm.sf,"")), _xlpm.computedResult,IF(AND(_xlpm.fam="#N/C",_xlpm.subfam="#N/C"),_xlpm.sf,IF(_xlpm.resultSubfam<>"",_xlpm.resultSubfam,IF(_xlpm.resultFam<>"",_xlpm.resultFam,IF(_xlpm.resultSf<>"",_xlpm.resultSf,"")))), _xlpm.fallback,IF(IFERROR(B11,"#N/C")="#N/C",A11,IF(IFERROR(C11,"#N/C")="#N/C",B11,IF(IFERROR(D11,"#N/C")="#N/C",C11,IF(IFERROR(E11,"#N/C")="#N/C",D11,IF(IFERROR(F11,"#N/C")="#N/C",E11,IF(IFERROR(G11,"#N/C")="#N/C",F11,"#N/C")))))), _xlpm.finalResult,IF(OR(_xlpm.computedResult="",_xlpm.computedResult="#N/C"),_xlpm.fallback,_xlpm.computedResult), INDEX(_xlpm.finalResult,1))} -> leaf_beetle | K11: =+CONCATENATE(A11,".",B11,".",C11,".",D11,".",E11,".",F11,".",G11,".",H11,".",I11) -> Insecta.Coleoptera.Polyphaga.Cucujiformia.Chrysomeloidea.Chrysomelidae.Criocerinae.Oulema.#N/C | L11: =+COUNTIF(Monitoring!#REF!,K11) -> #REF!
A12: Insecta | B12: Coleoptera | C12: Polyphaga | D12: =+IFERROR(IF(E12="#N/C","#N/C",INDEX('ClassificationClasses'!D:D,MATCH(E12,'ClassificationClasses'!E:E,0))),"ERROR") -> Cucujiformia | E12: Chrysomeloidea | F12: Chrysomelidae | G12: Galerucinae | H12: #N/C | I12: #N/C | J12: {=_xlfn.LET(_xlpm.cls,A12, _xlpm.ord,IFERROR(B12,"#N/C"), _xlpm.subord,IFERROR(C12,"#N/C"), _xlpm.infr,IFERROR(D12,"#N/C"), _xlpm.sf,IFERROR(E12,"#N/C"), _xlpm.fam,IFERROR(F12,"#N/C"), _xlpm.subfam,IF(TRIM(G12)="-","#N/C",IFERROR(G12,"#N/C")), _xlpm.subfamMatch,IFERROR(_xlfn._xlws.FILTER(ClassificationClasses[Classification Class],(ClassificationClasses[Class]=_xlpm.cls)*(ClassificationClasses[Order]=_xlpm.ord)*(ClassificationClasses[Suborder]=_xlpm.subord)*(ClassificationClasses[Infraorder]=_xlpm.infr)*(ClassificationClasses[Superfamily]=_xlpm.sf)*(ClassificationClasses[Family]=_xlpm.fam)*(ClassificationClasses[Subfamily]=_xlpm.subfam),""),""), _xlpm.uniqueSubfam,IF(_xlpm.subfamMatch="","",_xlfn.UNIQUE(_xlpm.subfamMatch)), _xlpm.numUniqueSubfam,IF(_xlpm.uniqueSubfam="",0,ROWS(_xlpm.uniqueSubfam)), _xlpm.resultSubfam,IF(_xlpm.numUniqueSubfam=1,INDEX(_xlpm.uniqueSubfam,1),IF(_xlpm.numUniqueSubfam>=1,_xlpm.subfam,"")), _xlpm.famMatch,IFERROR(_xlfn._xlws.FILTER(ClassificationClasses[Classification Class],(ClassificationClasses[Class]=_xlpm.cls)*(ClassificationClasses[Order]=_xlpm.ord)*(ClassificationClasses[Suborder]=_xlpm.subord)*(ClassificationClasses[Infraorder]=_xlpm.infr)*(ClassificationClasses[Superfamily]=_xlpm.sf)*(ClassificationClasses[Family]=_xlpm.fam),""),""), _xlpm.uniqueFam,IF(_xlpm.famMatch="","",_xlfn.UNIQUE(_xlpm.famMatch)), _xlpm.numUniqueFam,IF(_xlpm.uniqueFam="",0,ROWS(_xlpm.uniqueFam)), _xlpm.resultFam,IF(_xlpm.numUniqueFam=1,INDEX(_xlpm.uniqueFam,1),IF(_xlpm.numUniqueFam>=1,_xlpm.fam,"")), _xlpm.sfMatch,IFERROR(_xlfn._xlws.FILTER(ClassificationClasses[Classification Class],(ClassificationClasses[Class]=_xlpm.cls)*(ClassificationClasses[Order]=_xlpm.ord)*(ClassificationClasses[Suborder]=_xlpm.subord)*(ClassificationClasses[Infraorder]=_xlpm.infr)*(ClassificationClasses[Superfamily]=_xlpm.sf),""),""), _xlpm.uniqueSf,IF(_xlpm.sfMatch="","",_xlfn.UNIQUE(_xlpm.sfMatch)), _xlpm.numUniqueSf,IF(_xlpm.uniqueSf="",0,ROWS(_xlpm.uniqueSf)), _xlpm.resultSf,IF(_xlpm.numUniqueSf=1,INDEX(_xlpm.uniqueSf,1),IF(_xlpm.numUniqueSf>=1,_xlpm.sf,"")), _xlpm.computedResult,IF(AND(_xlpm.fam="#N/C",_xlpm.subfam="#N/C"),_xlpm.sf,IF(_xlpm.resultSubfam<>"",_xlpm.resultSubfam,IF(_xlpm.resultFam<>"",_xlpm.resultFam,IF(_xlpm.resultSf<>"",_xlpm.resultSf,"")))), _xlpm.fallback,IF(IFERROR(B12,"#N/C")="#N/C",A12,IF(IFERROR(C12,"#N/C")="#N/C",B12,IF(IFERROR(D12,"#N/C")="#N/C",C12,IF(IFERROR(E12,"#N/C")="#N/C",D12,IF(IFERROR(F12,"#N/C")="#N/C",E12,IF(IFERROR(G12,"#N/C")="#N/C",F12,"#N/C")))))), _xlpm.finalResult,IF(OR(_xlpm.computedResult="",_xlpm.computedResult="#N/C"),_xlpm.fallback,_xlpm.computedResult), INDEX(_xlpm.finalResult,1))} -> leaf_beetle | K12: =+CONCATENATE(A12,".",B12,".",C12,".",D12,".",E12,".",F12,".",G12,".",H12,".",I12) -> Insecta.Coleoptera.Polyphaga.Cucujiformia.Chrysomeloidea.Chrysomelidae.Galerucinae.#N/C.#N/C | L12: =+COUNTIF(Monitoring!#REF!,K12) -> #REF!
A13: Insecta | B13: Coleoptera | C13: Polyphaga | D13: =+IFERROR(IF(E13="#N/C","#N/C",INDEX('ClassificationClasses'!D:D,MATCH(E13,'ClassificationClasses'!E:E,0))),"ERROR") -> Cucujiformia | E13: Chrysomeloidea | F13: Chrysomelidae | G13: Galerucinae | H13: Psylliodes | I13: #N/C | J13: {=_xlfn.LET(_xlpm.cls,A13, _xlpm.ord,IFERROR(B13,"#N/C"), _xlpm.subord,IFERROR(C13,"#N/C"), _xlpm.infr,IFERROR(D13,"#N/C"), _xlpm.sf,IFERROR(E13,"#N/C"), _xlpm.fam,IFERROR(F13,"#N/C"), _xlpm.subfam,IF(TRIM(G13)="-","#N/C",IFERROR(G13,"#N/C")), _xlpm.subfamMatch,IFERROR(_xlfn._xlws.FILTER(ClassificationClasses[Classification Class],(ClassificationClasses[Class]=_xlpm.cls)*(ClassificationClasses[Order]=_xlpm.ord)*(ClassificationClasses[Suborder]=_xlpm.subord)*(ClassificationClasses[Infraorder]=_xlpm.infr)*(ClassificationClasses[Superfamily]=_xlpm.sf)*(ClassificationClasses[Family]=_xlpm.fam)*(ClassificationClasses[Subfamily]=_xlpm.subfam),""),""), _xlpm.uniqueSubfam,IF(_xlpm.subfamMatch="","",_xlfn.UNIQUE(_xlpm.subfamMatch)), _xlpm.numUniqueSubfam,IF(_xlpm.uniqueSubfam="",0,ROWS(_xlpm.uniqueSubfam)), _xlpm.resultSubfam,IF(_xlpm.numUniqueSubfam=1,INDEX(_xlpm.uniqueSubfam,1),IF(_xlpm.numUniqueSubfam>=1,_xlpm.subfam,"")), _xlpm.famMatch,IFERROR(_xlfn._xlws.FILTER(ClassificationClasses[Classification Class],(ClassificationClasses[Class]=_xlpm.cls)*(ClassificationClasses[Order]=_xlpm.ord)*(ClassificationClasses[Suborder]=_xlpm.subord)*(ClassificationClasses[Infraorder]=_xlpm.infr)*(ClassificationClasses[Superfamily]=_xlpm.sf)*(ClassificationClasses[Family]=_xlpm.fam),""),""), _xlpm.uniqueFam,IF(_xlpm.famMatch="","",_xlfn.UNIQUE(_xlpm.famMatch)), _xlpm.numUniqueFam,IF(_xlpm.uniqueFam="",0,ROWS(_xlpm.uniqueFam)), _xlpm.resultFam,IF(_xlpm.numUniqueFam=1,INDEX(_xlpm.uniqueFam,1),IF(_xlpm.numUniqueFam>=1,_xlpm.fam,"")), _xlpm.sfMatch,IFERROR(_xlfn._xlws.FILTER(ClassificationClasses[Classification Class],(ClassificationClasses[Class]=_xlpm.cls)*(ClassificationClasses[Order]=_xlpm.ord)*(ClassificationClasses[Suborder]=_xlpm.subord)*(ClassificationClasses[Infraorder]=_xlpm.infr)*(ClassificationClasses[Superfamily]=_xlpm.sf),""),""), _xlpm.uniqueSf,IF(_xlpm.sfMatch="","",_xlfn.UNIQUE(_xlpm.sfMatch)), _xlpm.numUniqueSf,IF(_xlpm.uniqueSf="",0,ROWS(_xlpm.uniqueSf)), _xlpm.resultSf,IF(_xlpm.numUniqueSf=1,INDEX(_xlpm.uniqueSf,1),IF(_xlpm.numUniqueSf>=1,_xlpm.sf,"")), _xlpm.computedResult,IF(AND(_xlpm.fam="#N/C",_xlpm.subfam="#N/C"),_xlpm.sf,IF(_xlpm.resultSubfam<>"",_xlpm.resultSubfam,IF(_xlpm.resultFam<>"",_xlpm.resultFam,IF(_xlpm.resultSf<>"",_xlpm.resultSf,"")))), _xlpm.fallback,IF(IFERROR(B13,"#N/C")="#N/C",A13,IF(IFERROR(C13,"#N/C")="#N/C",B13,IF(IFERROR(D13,"#N/C")="#N/C",C13,IF(IFERROR(E13,"#N/C")="#N/C",D13,IF(IFERROR(F13,"#N/C")="#N/C",E13,IF(IFERROR(G13,"#N/C")="#N/C",F13,"#N/C")))))), _xlpm.finalResult,IF(OR(_xlpm.computedResult="",_xlpm.computedResult="#N/C"),_xlpm.fallback,_xlpm.computedResult), INDEX(_xlpm.finalResult,1))} -> leaf_beetle | K13: =+CONCATENATE(A13,".",B13,".",C13,".",D13,".",E13,".",F13,".",G13,".",H13,".",I13) -> Insecta.Coleoptera.Polyphaga.Cucujiformia.Chrysomeloidea.Chrysomelidae.Galerucinae.Psylliodes.#N/C | L13: =+COUNTIF(Monitoring!#REF!,K13) -> #REF!
... A32: Insecta | B32: Coleoptera | C32: Polyphaga | D32: =+IFERROR(IF(E32="#N/C","#N/C",INDEX('ClassificationClasses'!D:D,MATCH(E32,'ClassificationClasses'!E:E,0))),"ERROR") -> Cucujiformia | E32: Tenebrionoidea | F32: Oedemeridae | G32: Nacerdinae | H32: Chrysanthia | I32: #N/C | J32: {=_xlfn.LET(_xlpm.cls,A32, _xlpm.ord,IFERROR(B32,"#N/C"), _xlpm.subord,IFERROR(C32,"#N/C"), _xlpm.infr,IFERROR(D32,"#N/C"), _xlpm.sf,IFERROR(E32,"#N/C"), _xlpm.fam,IFERROR(F32,"#N/C"), _xlpm.subfam,IF(TRIM(G32)="-","#N/C",IFERROR(G32,"#N/C")), _xlpm.subfamMatch,IFERROR(_xlfn._xlws.FILTER(ClassificationClasses[Classification Class],(ClassificationClasses[Class]=_xlpm.cls)*(ClassificationClasses[Order]=_xlpm.ord)*(ClassificationClasses[Suborder]=_xlpm.subord)*(ClassificationClasses[Infraorder]=_xlpm.infr)*(ClassificationClasses[Superfamily]=_xlpm.sf)*(ClassificationClasses[Family]=_xlpm.fam)*(ClassificationClasses[Subfamily]=_xlpm.subfam),""),""), _xlpm.uniqueSubfam,IF(_xlpm.subfamMatch="","",_xlfn.UNIQUE(_xlpm.subfamMatch)), _xlpm.numUniqueSubfam,IF(_xlpm.uniqueSubfam="",0,ROWS(_xlpm.uniqueSubfam)), _xlpm.resultSubfam,IF(_xlpm.numUniqueSubfam=1,INDEX(_xlpm.uniqueSubfam,1),IF(_xlpm.numUniqueSubfam>=1,_xlpm.subfam,"")), _xlpm.famMatch,IFERROR(_xlfn._xlws.FILTER(ClassificationClasses[Classification Class],(ClassificationClasses[Class]=_xlpm.cls)*(ClassificationClasses[Order]=_xlpm.ord)*(ClassificationClasses[Suborder]=_xlpm.subord)*(ClassificationClasses[Infraorder]=_xlpm.infr)*(ClassificationClasses[Superfamily]=_xlpm.sf)*(ClassificationClasses[Family]=_xlpm.fam),""),""), _xlpm.uniqueFam,IF(_xlpm.famMatch="","",_xlfn.UNIQUE(_xlpm.famMatch)), _xlpm.numUniqueFam,IF(_xlpm.uniqueFam="",0,ROWS(_xlpm.uniqueFam)), _xlpm.resultFam,IF(_xlpm.numUniqueFam=1,INDEX(_xlpm.uniqueFam,1),IF(_xlpm.numUniqueFam>=1,_xlpm.fam,"")), _xlpm.sfMatch,IFERROR(_xlfn._xlws.FILTER(ClassificationClasses[Classification Class],(ClassificationClasses[Class]=_xlpm.cls)*(ClassificationClasses[Order]=_xlpm.ord)*(ClassificationClasses[Suborder]=_xlpm.subord)*(ClassificationClasses[Infraorder]=_xlpm.infr)*(ClassificationClasses[Superfamily]=_xlpm.sf),""),""), _xlpm.uniqueSf,IF(_xlpm.sfMatch="","",_xlfn.UNIQUE(_xlpm.sfMatch)), _xlpm.numUniqueSf,IF(_xlpm.uniqueSf="",0,ROWS(_xlpm.uniqueSf)), _xlpm.resultSf,IF(_xlpm.numUniqueSf=1,INDEX(_xlpm.uniqueSf,1),IF(_xlpm.numUniqueSf>=1,_xlpm.sf,"")), _xlpm.computedResult,IF(AND(_xlpm.fam="#N/C",_xlpm.subfam="#N/C"),_xlpm.sf,IF(_xlpm.resultSubfam<>"",_xlpm.resultSubfam,IF(_xlpm.resultFam<>"",_xlpm.resultFam,IF(_xlpm.resultSf<>"",_xlpm.resultSf,"")))), _xlpm.fallback,IF(IFERROR(B32,"#N/C")="#N/C",A32,IF(IFERROR(C32,"#N/C")="#N/C",B32,IF(IFERROR(D32,"#N/C")="#N/C",C32,IF(IFERROR(E32,"#N/C")="#N/C",D32,IF(IFERROR(F32,"#N/C")="#N/C",E32,IF(IFERROR(G32,"#N/C")="#N/C",F32,"#N/C")))))), _xlpm.finalResult,IF(OR(_xlpm.computedResult="",_xlpm.computedResult="#N/C"),_xlpm.fallback,_xlpm.computedResult), INDEX(_xlpm.finalResult,1))} -> pollen_feeding_beetle | K32: =+CONCATENATE(A32,".",B32,".",C32,".",D32,".",E32,".",F32,".",G32,".",H32,".",I32) -> Insecta.Coleoptera.Polyphaga.Cucujiformia.Tenebrionoidea.Oedemeridae.Nacerdinae.Chrysanthia.#N/C | L32: =+COUNTIF(Monitoring!#REF!,K32) -> #REF!
A33: Insecta | B33: Dermaptera | C33: Forficulina | D33: Epidermaptera | E33: Forficuloidea | F33: Forficulidae | G33: Forficulinae | H33: #N/C | I33: #N/C | J33: {=_xlfn.LET(_xlpm.cls,A33, _xlpm.ord,IFERROR(B33,"#N/C"), _xlpm.subord,IFERROR(C33,"#N/C"), _xlpm.infr,IFERROR(D33,"#N/C"), _xlpm.sf,IFERROR(E33,"#N/C"), _xlpm.fam,IFERROR(F33,"#N/C"), _xlpm.subfam,IF(TRIM(G33)="-","#N/C",IFERROR(G33,"#N/C")), _xlpm.subfamMatch,IFERROR(_xlfn._xlws.FILTER(ClassificationClasses[Classification Class],(ClassificationClasses[Class]=_xlpm.cls)*(ClassificationClasses[Order]=_xlpm.ord)*(ClassificationClasses[Suborder]=_xlpm.subord)*(ClassificationClasses[Infraorder]=_xlpm.infr)*(ClassificationClasses[Superfamily]=_xlpm.sf)*(ClassificationClasses[Family]=_xlpm.fam)*(ClassificationClasses[Subfamily]=_xlpm.subfam),""),""), _xlpm.uniqueSubfam,IF(_xlpm.subfamMatch="","",_xlfn.UNIQUE(_xlpm.subfamMatch)), _xlpm.numUniqueSubfam,IF(_xlpm.uniqueSubfam="",0,ROWS(_xlpm.uniqueSubfam)), _xlpm.resultSubfam,IF(_xlpm.numUniqueSubfam=1,INDEX(_xlpm.uniqueSubfam,1),IF(_xlpm.numUniqueSubfam>=1,_xlpm.subfam,"")), _xlpm.famMatch,IFERROR(_xlfn._xlws.FILTER(ClassificationClasses[Classification Class],(ClassificationClasses[Class]=_xlpm.cls)*(ClassificationClasses[Order]=_xlpm.ord)*(ClassificationClasses[Suborder]=_xlpm.subord)*(ClassificationClasses[Infraorder]=_xlpm.infr)*(ClassificationClasses[Superfamily]=_xlpm.sf)*(ClassificationClasses[Family]=_xlpm.fam),""),""), _xlpm.uniqueFam,IF(_xlpm.famMatch="","",_xlfn.UNIQUE(_xlpm.famMatch)), _xlpm.numUniqueFam,IF(_xlpm.uniqueFam="",0,ROWS(_xlpm.uniqueFam)), _xlpm.resultFam,IF(_xlpm.numUniqueFam=1,INDEX(_xlpm.uniqueFam,1),IF(_xlpm.numUniqueFam>=1,_xlpm.fam,"")), _xlpm.sfMatch,IFERROR(_xlfn._xlws.FILTER(ClassificationClasses[Classification Class],(ClassificationClasses[Class]=_xlpm.cls)*(ClassificationClasses[Order]=_xlpm.ord)*(ClassificationClasses[Suborder]=_xlpm.subord)*(ClassificationClasses[Infraorder]=_xlpm.infr)*(ClassificationClasses[Superfamily]=_xlpm.sf),""),""), _xlpm.uniqueSf,IF(_xlpm.sfMatch="","",_xlfn.UNIQUE(_xlpm.sfMatch)), _xlpm.numUniqueSf,IF(_xlpm.uniqueSf="",0,ROWS(_xlpm.uniqueSf)), _xlpm.resultSf,IF(_xlpm.numUniqueSf=1,INDEX(_xlpm.uniqueSf,1),IF(_xlpm.numUniqueSf>=1,_xlpm.sf,"")), _xlpm.computedResult,IF(AND(_xlpm.fam="#N/C",_xlpm.subfam="#N/C"),_xlpm.sf,IF(_xlpm.resultSubfam<>"",_xlpm.resultSubfam,IF(_xlpm.resultFam<>"",_xlpm.resultFam,IF(_xlpm.resultSf<>"",_xlpm.resultSf,"")))), _xlpm.fallback,IF(IFERROR(B33,"#N/C")="#N/C",A33,IF(IFERROR(C33,"#N/C")="#N/C",B33,IF(IFERROR(D33,"#N/C")="#N/C",C33,IF(IFERROR(E33,"#N/C")="#N/C",D33,IF(IFERROR(F33,"#N/C")="#N/C",E33,IF(IFERROR(G33,"#N/C")="#N/C",F33,"#N/C")))))), _xlpm.finalResult,IF(OR(_xlpm.computedResult="",_xlpm.computedResult="#N/C"),_xlpm.fallback,_xlpm.computedResult), INDEX(_xlpm.finalResult,1))} -> earwig | K33: =+CONCATENATE(A33,".",B33,".",C33,".",D33,".",E33,".",F33,".",G33,".",H33,".",I33) -> Insecta.Dermaptera.Forficulina.Epidermaptera.Forficuloidea.Forficulidae.Forficulinae.#N/C.#N/C | L33: =+COUNTIF(Monitoring!#REF!,K33) -> #REF!
A34: Insecta | B34: Dermaptera | C34: Forficulina | D34: Epidermaptera | E34: Forficuloidea | F34: Forficulidae | G34: Forficulinae | H34: Forficula | I34: #N/C | J34: {=_xlfn.LET(_xlpm.cls,A34, _xlpm.ord,IFERROR(B34,"#N/C"), _xlpm.subord,IFERROR(C34,"#N/C"), _xlpm.infr,IFERROR(D34,"#N/C"), _xlpm.sf,IFERROR(E34,"#N/C"), _xlpm.fam,IFERROR(F34,"#N/C"), _xlpm.subfam,IF(TRIM(G34)="-","#N/C",IFERROR(G34,"#N/C")), _xlpm.subfamMatch,IFERROR(_xlfn._xlws.FILTER(ClassificationClasses[Classification Class],(ClassificationClasses[Class]=_xlpm.cls)*(ClassificationClasses[Order]=_xlpm.ord)*(ClassificationClasses[Suborder]=_xlpm.subord)*(ClassificationClasses[Infraorder]=_xlpm.infr)*(ClassificationClasses[Superfamily]=_xlpm.sf)*(ClassificationClasses[Family]=_xlpm.fam)*(ClassificationClasses[Subfamily]=_xlpm.subfam),""),""), _xlpm.uniqueSubfam,IF(_xlpm.subfamMatch="","",_xlfn.UNIQUE(_xlpm.subfamMatch)), _xlpm.numUniqueSubfam,IF(_xlpm.uniqueSubfam="",0,ROWS(_xlpm.uniqueSubfam)), _xlpm.resultSubfam,IF(_xlpm.numUniqueSubfam=1,INDEX(_xlpm.uniqueSubfam,1),IF(_xlpm.numUniqueSubfam>=1,_xlpm.subfam,"")), _xlpm.famMatch,IFERROR(_xlfn._xlws.FILTER(ClassificationClasses[Classification Class],(ClassificationClasses[Class]=_xlpm.cls)*(ClassificationClasses[Order]=_xlpm.ord)*(ClassificationClasses[Suborder]=_xlpm.subord)*(ClassificationClasses[Infraorder]=_xlpm.infr)*(ClassificationClasses[Superfamily]=_xlpm.sf)*(ClassificationClasses[Family]=_xlpm.fam),""),""), _xlpm.uniqueFam,IF(_xlpm.famMatch="","",_xlfn.UNIQUE(_xlpm.famMatch)), _xlpm.numUniqueFam,IF(_xlpm.uniqueFam="",0,ROWS(_xlpm.uniqueFam)), _xlpm.resultFam,IF(_xlpm.numUniqueFam=1,INDEX(_xlpm.uniqueFam,1),IF(_xlpm.numUniqueFam>=1,_xlpm.fam,"")), _xlpm.sfMatch,IFERROR(_xlfn._xlws.FILTER(ClassificationClasses[Classification Class],(ClassificationClasses[Class]=_xlpm.cls)*(ClassificationClasses[Order]=_xlpm.ord)*(ClassificationClasses[Suborder]=_xlpm.subord)*(ClassificationClasses[Infraorder]=_xlpm.infr)*(ClassificationClasses[Superfamily]=_xlpm.sf),""),""), _xlpm.uniqueSf,IF(_xlpm.sfMatch="","",_xlfn.UNIQUE(_xlpm.sfMatch)), _xlpm.numUniqueSf,IF(_xlpm.uniqueSf="",0,ROWS(_xlpm.uniqueSf)), _xlpm.resultSf,IF(_xlpm.numUniqueSf=1,INDEX(_xlpm.uniqueSf,1),IF(_xlpm.numUniqueSf>=1,_xlpm.sf,"")), _xlpm.computedResult,IF(AND(_xlpm.fam="#N/C",_xlpm.subfam="#N/C"),_xlpm.sf,IF(_xlpm.resultSubfam<>"",_xlpm.resultSubfam,IF(_xlpm.resultFam<>"",_xlpm.resultFam,IF(_xlpm.resultSf<>"",_xlpm.resultSf,"")))), _xlpm.fallback,IF(IFERROR(B34,"#N/C")="#N/C",A34,IF(IFERROR(C34,"#N/C")="#N/C",B34,IF(IFERROR(D34,"#N/C")="#N/C",C34,IF(IFERROR(E34,"#N/C")="#N/C",D34,IF(IFERROR(F34,"#N/C")="#N/C",E34,IF(IFERROR(G34,"#N/C")="#N/C",F34,"#N/C")))))), _xlpm.finalResult,IF(OR(_xlpm.computedResult="",_xlpm.computedResult="#N/C"),_xlpm.fallback,_xlpm.computedResult), INDEX(_xlpm.finalResult,1))} -> earwig | K34: =+CONCATENATE(A34,".",B34,".",C34,".",D34,".",E34,".",F34,".",G34,".",H34,".",I34) -> Insecta.Dermaptera.Forficulina.Epidermaptera.Forficuloidea.Forficulidae.Forficulinae.Forficula.#N/C | L34: =+COUNTIF(Monitoring!#REF!,K34) -> #REF!
A35: Insecta | B35: Diptera | C35: #N/C | D35: =+IFERROR(IF(E35="#N/C","#N/C",INDEX('ClassificationClasses'!D:D,MATCH(E35,'ClassificationClasses'!E:E,0))),"ERROR") -> #N/C | E35: #N/C | F35: #N/C | G35: #N/C | H35: #N/C | I35: #N/C | J35: {=_xlfn.LET(_xlpm.cls,A35, _xlpm.ord,IFERROR(B35,"#N/C"), _xlpm.subord,IFERROR(C35,"#N/C"), _xlpm.infr,IFERROR(D35,"#N/C"), _xlpm.sf,IFERROR(E35,"#N/C"), _xlpm.fam,IFERROR(F35,"#N/C"), _xlpm.subfam,IF(TRIM(G35)="-","#N/C",IFERROR(G35,"#N/C")), _xlpm.subfamMatch,IFERROR(_xlfn._xlws.FILTER(ClassificationClasses[Classification Class],(ClassificationClasses[Class]=_xlpm.cls)*(ClassificationClasses[Order]=_xlpm.ord)*(ClassificationClasses[Suborder]=_xlpm.subord)*(ClassificationClasses[Infraorder]=_xlpm.infr)*(ClassificationClasses[Superfamily]=_xlpm.sf)*(ClassificationClasses[Family]=_xlpm.fam)*(ClassificationClasses[Subfamily]=_xlpm.subfam),""),""), _xlpm.uniqueSubfam,IF(_xlpm.subfamMatch="","",_xlfn.UNIQUE(_xlpm.subfamMatch)), _xlpm.numUniqueSubfam,IF(_xlpm.uniqueSubfam="",0,ROWS(_xlpm.uniqueSubfam)), _xlpm.resultSubfam,IF(_xlpm.numUniqueSubfam=1,INDEX(_xlpm.uniqueSubfam,1),IF(_xlpm.numUniqueSubfam>=1,_xlpm.subfam,"")), _xlpm.famMatch,IFERROR(_xlfn._xlws.FILTER(ClassificationClasses[Classification Class],(ClassificationClasses[Class]=_xlpm.cls)*(ClassificationClasses[Order]=_xlpm.ord)*(ClassificationClasses[Suborder]=_xlpm.subord)*(ClassificationClasses[Infraorder]=_xlpm.infr)*(ClassificationClasses[Superfamily]=_xlpm.sf)*(ClassificationClasses[Family]=_xlpm.fam),""),""), _xlpm.uniqueFam,IF(_xlpm.famMatch="","",_xlfn.UNIQUE(_xlpm.famMatch)), _xlpm.numUniqueFam,IF(_xlpm.uniqueFam="",0,ROWS(_xlpm.uniqueFam)), _xlpm.resultFam,IF(_xlpm.numUniqueFam=1,INDEX(_xlpm.uniqueFam,1),IF(_xlpm.numUniqueFam>=1,_xlpm.fam,"")), _xlpm.sfMatch,IFERROR(_xlfn._xlws.FILTER(ClassificationClasses[Classification Class],(ClassificationClasses[Class]=_xlpm.cls)*(ClassificationClasses[Order]=_xlpm.ord)*(ClassificationClasses[Suborder]=_xlpm.subord)*(ClassificationClasses[Infraorder]=_xlpm.infr)*(ClassificationClasses[Superfamily]=_xlpm.sf),""),""), _xlpm.uniqueSf,IF(_xlpm.sfMatch="","",_xlfn.UNIQUE(_xlpm.sfMatch)), _xlpm.numUniqueSf,IF(_xlpm.uniqueSf="",0,ROWS(_xlpm.uniqueSf)), _xlpm.resultSf,IF(_xlpm.numUniqueSf=1,INDEX(_xlpm.uniqueSf,1),IF(_xlpm.numUniqueSf>=1,_xlpm.sf,"")), _xlpm.computedResult,IF(AND(_xlpm.fam="#N/C",_xlpm.subfam="#N/C"),_xlpm.sf,IF(_xlpm.resultSubfam<>"",_xlpm.resultSubfam,IF(_xlpm.resultFam<>"",_xlpm.resultFam,IF(_xlpm.resultSf<>"",_xlpm.resultSf,"")))), _xlpm.fallback,IF(IFERROR(B35,"#N/C")="#N/C",A35,IF(IFERROR(C35,"#N/C")="#N/C",B35,IF(IFERROR(D35,"#N/C")="#N/C",C35,IF(IFERROR(E35,"#N/C")="#N/C",D35,IF(IFERROR(F35,"#N/C")="#N/C",E35,IF(IFERROR(G35,"#N/C")="#N/C",F35,"#N/C")))))), _xlpm.finalResult,IF(OR(_xlpm.computedResult="",_xlpm.computedResult="#N/C"),_xlpm.fallback,_xlpm.computedResult), INDEX(_xlpm.finalResult,1))} -> Diptera | K35: =+CONCATENATE(A35,".",B35,".",C35,".",D35,".",E35,".",F35,".",G35,".",H35,".",I35) -> Insecta.Diptera.#N/C.#N/C.#N/C.#N/C.#N/C.#N/C.#N/C | L35: =+COUNTIF(Monitoring!#REF!,K35) -> #REF!
A36: Insecta | B36: Diptera | C36: Brachycera | D36: =+IFERROR(IF(E36="#N/C","#N/C",INDEX('ClassificationClasses'!D:D,MATCH(E36,'ClassificationClasses'!E:E,0))),"ERROR") -> #N/C | E36: #N/C | F36: #N/C | G36: #N/C | H36: #N/C | I36: #N/C | J36: {=_xlfn.LET(_xlpm.cls,A36, _xlpm.ord,IFERROR(B36,"#N/C"), _xlpm.subord,IFERROR(C36,"#N/C"), _xlpm.infr,IFERROR(D36,"#N/C"), _xlpm.sf,IFERROR(E36,"#N/C"), _xlpm.fam,IFERROR(F36,"#N/C"), _xlpm.subfam,IF(TRIM(G36)="-","#N/C",IFERROR(G36,"#N/C")), _xlpm.subfamMatch,IFERROR(_xlfn._xlws.FILTER(ClassificationClasses[Classification Class],(ClassificationClasses[Class]=_xlpm.cls)*(ClassificationClasses[Order]=_xlpm.ord)*(ClassificationClasses[Suborder]=_xlpm.subord)*(ClassificationClasses[Infraorder]=_xlpm.infr)*(ClassificationClasses[Superfamily]=_xlpm.sf)*(ClassificationClasses[Family]=_xlpm.fam)*(ClassificationClasses[Subfamily]=_xlpm.subfam),""),""), _xlpm.uniqueSubfam,IF(_xlpm.subfamMatch="","",_xlfn.UNIQUE(_xlpm.subfamMatch)), _xlpm.numUniqueSubfam,IF(_xlpm.uniqueSubfam="",0,ROWS(_xlpm.uniqueSubfam)), _xlpm.resultSubfam,IF(_xlpm.numUniqueSubfam=1,INDEX(_xlpm.uniqueSubfam,1),IF(_xlpm.numUniqueSubfam>=1,_xlpm.subfam,"")), _xlpm.famMatch,IFERROR(_xlfn._xlws.FILTER(ClassificationClasses[Classification Class],(ClassificationClasses[Class]=_xlpm.cls)*(ClassificationClasses[Order]=_xlpm.ord)*(ClassificationClasses[Suborder]=_xlpm.subord)*(ClassificationClasses[Infraorder]=_xlpm.infr)*(ClassificationClasses[Superfamily]=_xlpm.sf)*(ClassificationClasses[Family]=_xlpm.fam),""),""), _xlpm.uniqueFam,IF(_xlpm.famMatch="","",_xlfn.UNIQUE(_xlpm.famMatch)), _xlpm.numUniqueFam,IF(_xlpm.uniqueFam="",0,ROWS(_xlpm.uniqueFam)), _xlpm.resultFam,IF(_xlpm.numUniqueFam=1,INDEX(_xlpm.uniqueFam,1),IF(_xlpm.numUniqueFam>=1,_xlpm.fam,"")), _xlpm.sfMatch,IFERROR(_xlfn._xlws.FILTER(ClassificationClasses[Classification Class],(ClassificationClasses[Class]=_xlpm.cls)*(ClassificationClasses[Order]=_xlpm.ord)*(ClassificationClasses[Suborder]=_xlpm.subord)*(ClassificationClasses[Infraorder]=_xlpm.infr)*(ClassificationClasses[Superfamily]=_xlpm.sf),""),""), _xlpm.uniqueSf,IF(_xlpm.sfMatch="","",_xlfn.UNIQUE(_xlpm.sfMatch)), _xlpm.numUniqueSf,IF(_xlpm.uniqueSf="",0,ROWS(_xlpm.uniqueSf)), _xlpm.resultSf,IF(_xlpm.numUniqueSf=1,INDEX(_xlpm.uniqueSf,1),IF(_xlpm.numUniqueSf>=1,_xlpm.sf,"")), _xlpm.computedResult,IF(AND(_xlpm.fam="#N/C",_xlpm.subfam="#N/C"),_xlpm.sf,IF(_xlpm.resultSubfam<>"",_xlpm.resultSubfam,IF(_xlpm.resultFam<>"",_xlpm.resultFam,IF(_xlpm.resultSf<>"",_xlpm.resultSf,"")))), _xlpm.fallback,IF(IFERROR(B36,"#N/C")="#N/C",A36,IF(IFERROR(C36,"#N/C")="#N/C",B36,IF(IFERROR(D36,"#N/C")="#N/C",C36,IF(IFERROR(E36,"#N/C")="#N/C",D36,IF(IFERROR(F36,"#N/C")="#N/C",E36,IF(IFERROR(G36,"#N/C")="#N/C",F36,"#N/C")))))), _xlpm.finalResult,IF(OR(_xlpm.computedResult="",_xlpm.computedResult="#N/C"),_xlpm.fallback,_xlpm.computedResult), INDEX(_xlpm.finalResult,1))} -> Brachycera | K36: =+CONCATENATE(A36,".",B36,".",C36,".",D36,".",E36,".",F36,".",G36,".",H36,".",I36) -> Insecta.Diptera.Brachycera.#N/C.#N/C.#N/C.#N/C.#N/C.#N/C | L36: =+COUNTIF(Monitoring!#REF!,K36) -> #REF!
A37: Insecta | B37: Diptera | C37: Brachycera | D37: =+IFERROR(IF(E37="#N/C","#N/C",INDEX('ClassificationClasses'!D:D,MATCH(E37,'ClassificationClasses'!E:E,0))),"ERROR") -> Asilomorpha | E37: Asiloidea | F37: Asilidae | G37: Asilinae | H37: #N/C | I37: #N/C | J37: {=_xlfn.LET(_xlpm.cls,A37, _xlpm.ord,IFERROR(B37,"#N/C"), _xlpm.subord,IFERROR(C37,"#N/C"), _xlpm.infr,IFERROR(D37,"#N/C"), _xlpm.sf,IFERROR(E37,"#N/C"), _xlpm.fam,IFERROR(F37,"#N/C"), _xlpm.subfam,IF(TRIM(G37)="-","#N/C",IFERROR(G37,"#N/C")), _xlpm.subfamMatch,IFERROR(_xlfn._xlws.FILTER(ClassificationClasses[Classification Class],(ClassificationClasses[Class]=_xlpm.cls)*(ClassificationClasses[Order]=_xlpm.ord)*(ClassificationClasses[Suborder]=_xlpm.subord)*(ClassificationClasses[Infraorder]=_xlpm.infr)*(ClassificationClasses[Superfamily]=_xlpm.sf)*(ClassificationClasses[Family]=_xlpm.fam)*(ClassificationClasses[Subfamily]=_xlpm.subfam),""),""), _xlpm.uniqueSubfam,IF(_xlpm.subfamMatch="","",_xlfn.UNIQUE(_xlpm.subfamMatch)), _xlpm.numUniqueSubfam,IF(_xlpm.uniqueSubfam="",0,ROWS(_xlpm.uniqueSubfam)), _xlpm.resultSubfam,IF(_xlpm.numUniqueSubfam=1,INDEX(_xlpm.uniqueSubfam,1),IF(_xlpm.numUniqueSubfam>=1,_xlpm.subfam,"")), _xlpm.famMatch,IFERROR(_xlfn._xlws.FILTER(ClassificationClasses[Classification Class],(ClassificationClasses[Class]=_xlpm.cls)*(ClassificationClasses[Order]=_xlpm.ord)*(ClassificationClasses[Suborder]=_xlpm.subord)*(ClassificationClasses[Infraorder]=_xlpm.infr)*(ClassificationClasses[Superfamily]=_xlpm.sf)*(ClassificationClasses[Family]=_xlpm.fam),""),""), _xlpm.uniqueFam,IF(_xlpm.famMatch="","",_xlfn.UNIQUE(_xlpm.famMatch)), _xlpm.numUniqueFam,IF(_xlpm.uniqueFam="",0,ROWS(_xlpm.uniqueFam)), _xlpm.resultFam,IF(_xlpm.numUniqueFam=1,INDEX(_xlpm.uniqueFam,1),IF(_xlpm.numUniqueFam>=1,_xlpm.fam,"")), _xlpm.sfMatch,IFERROR(_xlfn._xlws.FILTER(ClassificationClasses[Classification Class],(ClassificationClasses[Class]=_xlpm.cls)*(ClassificationClasses[Order]=_xlpm.ord)*(ClassificationClasses[Suborder]=_xlpm.subord)*(ClassificationClasses[Infraorder]=_xlpm.infr)*(ClassificationClasses[Superfamily]=_xlpm.sf),""),""), _xlpm.uniqueSf,IF(_xlpm.sfMatch="","",_xlfn.UNIQUE(_xlpm.sfMatch)), _xlpm.numUniqueSf,IF(_xlpm.uniqueSf="",0,ROWS(_xlpm.uniqueSf)), _xlpm.resultSf,IF(_xlpm.numUniqueSf=1,INDEX(_xlpm.uniqueSf,1),IF(_xlpm.numUniqueSf>=1,_xlpm.sf,"")), _xlpm.computedResult,IF(AND(_xlpm.fam="#N/C",_xlpm.subfam="#N/C"),_xlpm.sf,IF(_xlpm.resultSubfam<>"",_xlpm.resultSubfam,IF(_xlpm.resultFam<>"",_xlpm.resultFam,IF(_xlpm.resultSf<>"",_xlpm.resultSf,"")))), _xlpm.fallback,IF(IFERROR(B37,"#N/C")="#N/C",A37,IF(IFERROR(C37,"#N/C")="#N/C",B37,IF(IFERROR(D37,"#N/C")="#N/C",C37,IF(IFERROR(E37,"#N/C")="#N/C",D37,IF(IFERROR(F37,"#N/C")="#N/C",E37,IF(IFERROR(G37,"#N/C")="#N/C",F37,"#N/C")))))), _xlpm.finalResult,IF(OR(_xlpm.computedResult="",_xlpm.computedResult="#N/C"),_xlpm.fallback,_xlpm.computedResult), INDEX(_xlpm.finalResult,1))} -> robber_fly | K37: =+CONCATENATE(A37,".",B37,".",C37,".",D37,".",E37,".",F37,".",G37,".",H37,".",I37) -> Insecta.Diptera.Brachycera.Asilomorpha.Asiloidea.Asilidae.Asilinae.#N/C.#N/C | L37: =+COUNTIF(Monitoring!#REF!,K37) -> #REF!
A38: Insecta | B38: Diptera | C38: Brachycera | D38: =+IFERROR(IF(E38="#N/C","#N/C",INDEX('ClassificationClasses'!D:D,MATCH(E38,'ClassificationClasses'!E:E,0))),"ERROR") -> Asilomorpha | E38: Asiloidea | F38: Asilidae | G38: Asilinae | H38: Tolmerus | I38: #N/C | J38: {=_xlfn.LET(_xlpm.cls,A38, _xlpm.ord,IFERROR(B38,"#N/C"), _xlpm.subord,IFERROR(C38,"#N/C"), _xlpm.infr,IFERROR(D38,"#N/C"), _xlpm.sf,IFERROR(E38,"#N/C"), _xlpm.fam,IFERROR(F38,"#N/C"), _xlpm.subfam,IF(TRIM(G38)="-","#N/C",IFERROR(G38,"#N/C")), _xlpm.subfamMatch,IFERROR(_xlfn._xlws.FILTER(ClassificationClasses[Classification Class],(ClassificationClasses[Class]=_xlpm.cls)*(ClassificationClasses[Order]=_xlpm.ord)*(ClassificationClasses[Suborder]=_xlpm.subord)*(ClassificationClasses[Infraorder]=_xlpm.infr)*(ClassificationClasses[Superfamily]=_xlpm.sf)*(ClassificationClasses[Family]=_xlpm.fam)*(ClassificationClasses[Subfamily]=_xlpm.subfam),""),""), _xlpm.uniqueSubfam,IF(_xlpm.subfamMatch="","",_xlfn.UNIQUE(_xlpm.subfamMatch)), _xlpm.numUniqueSubfam,IF(_xlpm.uniqueSubfam="",0,ROWS(_xlpm.uniqueSubfam)), _xlpm.resultSubfam,IF(_xlpm.numUniqueSubfam=1,INDEX(_xlpm.uniqueSubfam,1),IF(_xlpm.numUniqueSubfam>=1,_xlpm.subfam,"")), _xlpm.famMatch,IFERROR(_xlfn._xlws.FILTER(ClassificationClasses[Classification Class],(ClassificationClasses[Class]=_xlpm.cls)*(ClassificationClasses[Order]=_xlpm.ord)*(ClassificationClasses[Suborder]=_xlpm.subord)*(ClassificationClasses[Infraorder]=_xlpm.infr)*(ClassificationClasses[Superfamily]=_xlpm.sf)*(ClassificationClasses[Family]=_xlpm.fam),""),""), _xlpm.uniqueFam,IF(_xlpm.famMatch="","",_xlfn.UNIQUE(_xlpm.famMatch)), _xlpm.numUniqueFam,IF(_xlpm.uniqueFam="",0,ROWS(_xlpm.uniqueFam)), _xlpm.resultFam,IF(_xlpm.numUniqueFam=1,INDEX(_xlpm.uniqueFam,1),IF(_xlpm.numUniqueFam>=1,_xlpm.fam,"")), _xlpm.sfMatch,IFERROR(_xlfn._xlws.FILTER(ClassificationClasses[Classification Class],(ClassificationClasses[Class]=_xlpm.cls)*(ClassificationClasses[Order]=_xlpm.ord)*(ClassificationClasses[Suborder]=_xlpm.subord)*(ClassificationClasses[Infraorder]=_xlpm.infr)*(ClassificationClasses[Superfamily]=_xlpm.sf),""),""), _xlpm.uniqueSf,IF(_xlpm.sfMatch="","",_xlfn.UNIQUE(_xlpm.sfMatch)), _xlpm.numUniqueSf,IF(_xlpm.uniqueSf="",0,ROWS(_xlpm.uniqueSf)), _xlpm.resultSf,IF(_xlpm.numUniqueSf=1,INDEX(_xlpm.uniqueSf,1),IF(_xlpm.numUniqueSf>=1,_xlpm.sf,"")), _xlpm.computedResult,IF(AND(_xlpm.fam="#N/C",_xlpm.subfam="#N/C"),_xlpm.sf,IF(_xlpm.resultSubfam<>"",_xlpm.resultSubfam,IF(_xlpm.resultFam<>"",_xlpm.resultFam,IF(_xlpm.resultSf<>"",_xlpm.resultSf,"")))), _xlpm.fallback,IF(IFERROR(B38,"#N/C")="#N/C",A38,IF(IFERROR(C38,"#N/C")="#N/C",B38,IF(IFERROR(D38,"#N/C")="#N/C",C38,IF(IFERROR(E38,"#N/C")="#N/C",D38,IF(IFERROR(F38,"#N/C")="#N/C",E38,IF(IFERROR(G38,"#N/C")="#N/C",F38,"#N/C")))))), _xlpm.finalResult,IF(OR(_xlpm.computedResult="",_xlpm.computedResult="#N/C"),_xlpm.fallback,_xlpm.computedResult), INDEX(_xlpm.finalResult,1))} -> robber_fly | K38: =+CONCATENATE(A38,".",B38,".",C38,".",D38,".",E38,".",F38,".",G38,".",H38,".",I38) -> Insecta.Diptera.Brachycera.Asilomorpha.Asiloidea.Asilidae.Asilinae.Tolmerus.#N/C | L38: =+COUNTIF(Monitoring!#REF!,K38) -> #REF!
