Workbook

Sheet Monitoring
A1: ID | B1: Date | C1: Video Name check in | D1: Video Name check out | E1: Check:in | F1: Check:out | G1: Duration | H1: Flight event | I1: Way out | J1: No. Videos | K1: iNat Sharing | L1: Class | M1: Order | N1: Suborder | O1: Infraorder | P1: Superfamily | Q1: Family | R1: Subfamily | S1: Genus | T1: Species
A2: 1 | B2: 44389 | C2: 2021-07-12_14-01-54 | D2: 2021-07-12_14-03-48 | E2: 44389.585 | F2: 44389.586 | G2: =F2-E2 -> 0.0013657407 | H2: yes | I2: exit | J2: =IF(ISBLANK(C2),"",IF(C2=D2, "1 video",CONCATENATE((+COUNTIFS(Video_List!$C:$C,"<=" &Monitoring!F2)-COUNTIFS(Video_List!$C:$C,"<=" &Monitoring!E2))+1," videos"))) -> 3 videos | K2: yes | L2: =+IFERROR(IF(M2="#N/C","#N/C",IF(N2=0,INDEX(Taxonomy_UniqueValues!A:A,MATCH(N2,Taxonomy_UniqueValues!C:C,0)),INDEX(Taxonomy_UniqueValues!A:A,MATCH(M2,Taxonomy_UniqueValues!B:B,0)))),"#N/C") -> Insecta | M2: =+IFERROR(IF(N2="#N/C","#N/C",IF(O2=0,INDEX(Taxonomy_UniqueValues!B:B,MATCH(O2,Taxonomy_UniqueValues!D:D,0)),INDEX(Taxonomy_UniqueValues!B:B,MATCH(N2,Taxonomy_UniqueValues!C:C,0)))),"#N/C") -> Diptera | N2: =+IFERROR(IF(O2="#N/C","#N/C",IF(P2=0,INDEX(Taxonomy_UniqueValues!C:C,MATCH(P2,Taxonomy_UniqueValues!E:E,0)),INDEX(Taxonomy_UniqueValues!C:C,MATCH(O2,Taxonomy_UniqueValues!D:D,0)))),"#N/C") -> Brachycera | O2: =+IFERROR(IF(P2="#N/C","#N/C",IF(Q2=0,INDEX(Taxonomy_UniqueValues!D:D,MATCH(Q2,Taxonomy_UniqueValues!F:F,0)),INDEX(Taxonomy_UniqueValues!D:D,MATCH(P2,Taxonomy_UniqueValues!E:E,0)))),"#N/C") -> Asilomorpha | P2: =+IFERROR(IF(Q2="#N/C","#N/C",IF(R2=0,INDEX(Taxonomy_UniqueValues!E:E,MATCH(R2,Taxonomy_UniqueValues!G:G,0)),INDEX(Taxonomy_UniqueValues!E:E,MATCH(Q2,Taxonomy_UniqueValues!F:F,0)))),"#N/C") -> Asiloidea | Q2: =+IFERROR(IF(R2="#N/C","#N/C",IF(S2=0,INDEX(Taxonomy_UniqueValues!F:F,MATCH(S2,Taxonomy_UniqueValues!H:H,0)),INDEX(Taxonomy_UniqueValues!F:F,MATCH(R2,Taxonomy_UniqueValues!G:G,0)))),"#N/C") -> Asilidae | R2: =+IFERROR(IF(S2="#N/C","#N/C",IF(T2=0,INDEX(Taxonomy_UniqueValues!G:G,MATCH(T2,Taxonomy_UniqueValues!I:I,0)),INDEX(Taxonomy_UniqueValues!G:G,MATCH(S2,Taxonomy_UniqueValues!H:H,0)))),"#N/C") -> Asilinae | S2: Tolmerus | T2: #N/C
A3: 2 | B3: 44389 | C3: 2021-07-12_14-59-17 | D3: 2021-07-12_14-59-17 | E3: 44389.625 | F3: 44389.625 | G3: =F3-E3 -> 4.62963e-05 | H3: yes | I3: exit | J3: =IF(ISBLANK(C3),"",IF(C3=D3, "1 video",CONCATENATE((+COUNTIFS(Video_List!$C:$C,"<=" &Monitoring!F3)-COUNTIFS(Video_List!$C:$C,"<=" &Monitoring!E3))+1," videos"))) -> 1 video | K3: yes | L3: Insecta | M3: Diptera | N3: Brachycera | O3: =+IFERROR(IF(P3="#N/C","#N/C",IF(Q3=0,INDEX(Taxonomy_UniqueValues!D:D,MATCH(Q3,Taxonomy_UniqueValues!F:F,0)),INDEX(Taxonomy_UniqueValues!D:D,MATCH(P3,Taxonomy_UniqueValues!E:E,0)))),"#N/C") -> #N/C | P3: #N/C | Q3: #N/C | R3: #N/C | S3: #N/C | T3: #N/C
A4: 3 | B4: 44389 | C4: 2021-07-12_15-05-25 | D4: 2021-07-12_15-05-25 | E4: 44389.629 | F4: 44389.629 | G4: =F4-E4 -> 0.00023148148 | H4: yes | I4: exit | J4: =IF(ISBLANK(C4),"",IF(C4=D4, "1 video",CONCATENATE((+COUNTIFS(Video_List!$C:$C,"<=" &Monitoring!F4)-COUNTIFS(Video_List!$C:$C,"<=" &Monitoring!E4))+1," videos"))) -> 1 video | K4: yes | L4: Insecta | M4: Hymenoptera | N4: Apocrita | O4: =+IFERROR(IF(P4="#N/C","#N/C",IF(Q4=0,INDEX(Taxonomy_UniqueValues!D:D,MATCH(Q4,Taxonomy_UniqueValues!F:F,0)),INDEX(Taxonomy_UniqueValues!D:D,MATCH(P4,Taxonomy_UniqueValues!E:E,0)))),"#N/C") -> #N/C | P4: #N/C | Q4: #N/C | R4: #N/C | S4: #N/C | T4: #N/C
A5: 4 | B5: 44389 | C5: 2021-07-12_15-19-53 | D5: 2021-07-12_15-19-53 | E5: 44389.639 | F5: 44389.639 | G5: =F5-E5 -> 4.62963e-05 | H5: yes | I5: exit | J5: =IF(ISBLANK(C5),"",IF(C5=D5, "1 video",CONCATENATE((+COUNTIFS(Video_List!$C:$C,"<=" &Monitoring!F5)-COUNTIFS(Video_List!$C:$C,"<=" &Monitoring!E5))+1," videos"))) -> 1 video | K5: no | L5: Insecta | M5: Diptera | N5: Brachycera | O5: =+IFERROR(IF(P5="#N/C","#N/C",IF(Q5=0,INDEX(Taxonomy_UniqueValues!D:D,MATCH(Q5,Taxonomy_UniqueValues!F:F,0)),INDEX(Taxonomy_UniqueValues!D:D,MATCH(P5,Taxonomy_UniqueValues!E:E,0)))),"#N/C") -> #N/C | P5: #N/C | Q5: #N/C | R5: #N/C | S5: #N/C | T5: #N/C
A6: 5 | B6: 44389 | C6: 2021-07-12_15-36-07 | D6: 2021-07-12_15-36-07 | E6: 44389.65 | F6: 44389.65 | G6: =F6-E6 -> 0.00033564815 | H6: yes | I6: exit | J6: =IF(ISBLANK(C6),"",IF(C6=D6, "1 video",CONCATENATE((+COUNTIFS(Video_List!$C:$C,"<=" &Monitoring!F6)-COUNTIFS(Video_List!$C:$C,"<=" &Monitoring!E6))+1," videos"))) -> 1 video | K6: no | L6: Insecta | M6: Diptera | N6: Brachycera | O6: =+IFERROR(IF(P6="#N/C","#N/C",IF(Q6=0,INDEX(Taxonomy_UniqueValues!D:D,MATCH(Q6,Taxonomy_UniqueValues!F:F,0)),INDEX(Taxonomy_UniqueValues!D:D,MATCH(P6,Taxonomy_UniqueValues!E:E,0)))),"#N/C") -> Muscomorpha | P6: Syrphoidea | Q6: Syrphidae | R6: Syrphinae | S6: Sphaerophoria | T6: #N/C
A7: 6 | B7: 44389 | C7: 2021-07-12_15-43-07 | D7: 2021-07-12_15-43-07 | E7: 44389.655 | F7: 44389.655 | G7: =F7-E7 -> 6.9444446e-05 | H7: yes | I7: exit | J7: =IF(ISBLANK(C7),"",IF(C7=D7, "1 video",CONCATENATE((+COUNTIFS(Video_List!$C:$C,"<=" &Monitoring!F7)-COUNTIFS(Video_List!$C:$C,"<=" &Monitoring!E7))+1," videos"))) -> 1 video | K7: no | L7: Insecta | M7: Diptera | N7: Brachycera | O7: =+IFERROR(IF(P7="#N/C","#N/C",IF(Q7=0,INDEX(Taxonomy_UniqueValues!D:D,MATCH(Q7,Taxonomy_UniqueValues!F:F,0)),INDEX(Taxonomy_UniqueValues!D:D,MATCH(P7,Taxonomy_UniqueValues!E:E,0)))),"#N/C") -> #N/C | P7: #N/C | Q7: #N/C | R7: #N/C | S7: #N/C | T7: #N/C
A8: 7 | B8: 44389 | C8: 2021-07-12_15-44-27 | D8: 2021-07-12_15-44-27 | E8: 44389.656 | F8: 44389.656 | G8: =F8-E8 -> 5.7870369e-05 | H8: yes | I8: exit | J8: =IF(ISBLANK(C8),"",IF(C8=D8, "1 video",CONCATENATE((+COUNTIFS(Video_List!$C:$C,"<=" &Monitoring!F8)-COUNTIFS(Video_List!$C:$C,"<=" &Monitoring!E8))+1," videos"))) -> 1 video | K8: no | L8: Insecta | M8: Diptera | N8: Brachycera | O8: =+IFERROR(IF(P8="#N/C","#N/C",IF(Q8=0,INDEX(Taxonomy_UniqueValues!D:D,MATCH(Q8,Taxonomy_UniqueValues!F:F,0)),INDEX(Taxonomy_UniqueValues!D:D,MATCH(P8,Taxonomy_UniqueValues!E:E,0)))),"#N/C") -> #N/C | P8: #N/C | Q8: #N/C | R8: #N/C | S8: #N/C | T8: #N/C
A9: 8 | B9: 44389 | C9: 2021-07-12_16-02-04 | D9: 2021-07-12_16-02-46 | E9: 44389.668 | F9: 44389.672 | G9: =F9-E9 -> 0.003587963 | H9: yes | I9: exit | J9: =IF(ISBLANK(C9),"",IF(C9=D9, "1 video",CONCATENATE((+COUNTIFS(Video_List!$C:$C,"<=" &Monitoring!F9)-COUNTIFS(Video_List!$C:$C,"<=" &Monitoring!E9))+1," videos"))) -> 2 videos | K9: no | L9: Insecta | M9: Diptera | N9: Brachycera | O9: =+IFERROR(IF(P9="#N/C","#N/C",IF(Q9=0,INDEX(Taxonomy_UniqueValues!D:D,MATCH(Q9,Taxonomy_UniqueValues!F:F,0)),INDEX(Taxonomy_UniqueValues!D:D,MATCH(P9,Taxonomy_UniqueValues!E:E,0)))),"#N/C") -> Muscomorpha | P9: Syrphoidea | Q9: Syrphidae | R9: Syrphinae | S9: #N/C | T9: #N/C
A10: 9 | B10: 44389 | C10: 2021-07-12_16-55-42 | D10: 2021-07-12_16-55-42 | E10: 44389.705 | F10: 44389.705 | G10: =F10-E10 -> 3.4722216e-05 | H10: yes | I10: exit | J10: =IF(ISBLANK(C10),"",IF(C10=D10, "1 video",CONCATENATE((+COUNTIFS(Video_List!$C:$C,"<=" &Monitoring!F10)-COUNTIFS(Video_List!$C:$C,"<=" &Monitoring!E10))+1," videos"))) -> 1 video | K10: no | L10: Insecta | M10: Diptera | N10: Brachycera | O10: =+IFERROR(IF(P10="#N/C","#N/C",IF(Q10=0,INDEX(Taxonomy_UniqueValues!D:D,MATCH(Q10,Taxonomy_UniqueValues!F:F,0)),INDEX(Taxonomy_UniqueValues!D:D,MATCH(P10,Taxonomy_UniqueValues!E:E,0)))),"#N/C") -> #N/C | P10: #N/C | Q10: #N/C | R10: #N/C | S10: #N/C | T10: #N/C
A11: 10 | B11: 44389 | C11: 2021-07-12_16-55-42 | D11: 2021-07-12_16-55-42 | E11: 44389.706 | F11: 44389.706 | G11: =F11-E11 -> 1.1574077e-05 | H11: ? | I11: ? | J11: =IF(ISBLANK(C11),"",IF(C11=D11, "1 video",CONCATENATE((+COUNTIFS(Video_List!$C:$C,"<=" &Monitoring!F11)-COUNTIFS(Video_List!$C:$C,"<=" &Monitoring!E11))+1," videos"))) -> 1 video | K11: yes | L11: Insecta | M11: Lepidoptera | N11: Glossata | O11: =+IFERROR(IF(P11="#N/C","#N/C",IF(Q11=0,INDEX(Taxonomy_UniqueValues!D:D,MATCH(Q11,Taxonomy_UniqueValues!F:F,0)),INDEX(Taxonomy_UniqueValues!D:D,MATCH(P11,Taxonomy_UniqueValues!E:E,0)))),"#N/C") -> Rhopalocera | P11: Papilionoidea | Q11: Hesperiidae | R11: Hesperiinae | S11: Thymelicus | T11: #N/C
A12: 11 | B12: 44389 | C12: 2021-07-12_17-03-54 | D12: 2021-07-12_17-03-54 | E12: 44389.711 | F12: 44389.711 | G12: =F12-E12 -> 8.1018516e-05 | H12: yes | I12: exit | J12: =IF(ISBLANK(C12),"",IF(C12=D12, "1 video",CONCATENATE((+COUNTIFS(Video_List!$C:$C,"<=" &Monitoring!F12)-COUNTIFS(Video_List!$C:$C,"<=" &Monitoring!E12))+1," videos"))) -> 1 video | K12: no | L12: Insecta | M12: Diptera | N12: Brachycera | O12: =+IFERROR(IF(P12="#N/C","#N/C",IF(Q12=0,INDEX(Taxonomy_UniqueValues!D:D,MATCH(Q12,Taxonomy_UniqueValues!F:F,0)),INDEX(Taxonomy_UniqueValues!D:D,MATCH(P12,Taxonomy_UniqueValues!E:E,0)))),"#N/C") -> Muscomorpha | P12: Ephydroidea | Q12: Drosophilidae | R12: Drosophilinae | S12: Scaptomyza | T12: #N/C
A13: 12 | B13: 44389 | C13: 2021-07-12_17-14-40 | D13: 2021-07-12_17-14-40 | E13: 44389.719 | F13: 44389.719 | G13: =F13-E13 -> 0.00011574075 | H13: yes | I13: exit | J13: =IF(ISBLANK(C13),"",IF(C13=D13, "1 video",CONCATENATE((+COUNTIFS(Video_List!$C:$C,"<=" &Monitoring!F13)-COUNTIFS(Video_List!$C:$C,"<=" &Monitoring!E13))+1," videos"))) -> 1 video | K13: no | L13: Insecta | M13: Diptera | N13: Brachycera | O13: =+IFERROR(IF(P13="#N/C","#N/C",IF(Q13=0,INDEX(Taxonomy_UniqueValues!D:D,MATCH(Q13,Taxonomy_UniqueValues!F:F,0)),INDEX(Taxonomy_UniqueValues!D:D,MATCH(P13,Taxonomy_UniqueValues!E:E,0)))),"#N/C") -> #N/C | P13: #N/C | Q13: #N/C | R13: #N/C | S13: #N/C | T13: #N/C
A14: 13 | B14: 44389 | C14: 2021-07-12_17-18-47 | D14: 2021-07-12_17-18-47 | E14: 44389.721 | F14: 44389.721 | G14: =F14-E14 -> 5.7870369e-05 | H14: yes | I14: exit | J14: =IF(ISBLANK(C14),"",IF(C14=D14, "1 video",CONCATENATE((+COUNTIFS(Video_List!$C:$C,"<=" &Monitoring!F14)-COUNTIFS(Video_List!$C:$C,"<=" &Monitoring!E14))+1," videos"))) -> 1 video | K14: no | L14: Insecta | M14: Diptera | N14: Brachycera | O14: =+IFERROR(IF(P14="#N/C","#N/C",IF(Q14=0,INDEX(Taxonomy_UniqueValues!D:D,MATCH(Q14,Taxonomy_UniqueValues!F:F,0)),INDEX(Taxonomy_UniqueValues!D:D,MATCH(P14,Taxonomy_UniqueValues!E:E,0)))),"#N/C") -> #N/C | P14: #N/C | Q14: #N/C | R14: #N/C | S14: #N/C | T14: #N/C
... A42: 41 | B42: 44390 | C42: 2021-07-13_09-44-49 | D42: 2021-07-13_09-44-49 | E42: 44390.406 | F42: 44390.406 | G42: =F42-E42 -> 5.7870369e-05 | H42: yes | I42: exit | J42: =IF(ISBLANK(C42),"",IF(C42=D42, "1 video",CONCATENATE((+COUNTIFS(Video_List!$C:$C,"<=" &Monitoring!F42)-COUNTIFS(Video_List!$C:$C,"<=" &Monitoring!E42))+1," videos"))) -> 1 video | K42: no | L42: Insecta | M42: Diptera | N42: Brachycera | O42: =+IFERROR(IF(P42="#N/C","#N/C",IF(Q42=0,INDEX(Taxonomy_UniqueValues!D:D,MATCH(Q42,Taxonomy_UniqueValues!F:F,0)),INDEX(Taxonomy_UniqueValues!D:D,MATCH(P42,Taxonomy_UniqueValues!E:E,0)))),"#N/C") -> #N/C | P42: #N/C | Q42: #N/C | R42: #N/C | S42: #N/C | T42: #N/C
A43: 42 | B43: 44390 | C43: 2021-07-13_09-52-48 | D43: 2021-07-13_09-52-48 | E43: 44390.412 | F43: 44390.412 | G43: =F43-E43 -> 9.2592592e-05 | H43: no | I43: exit | J43: =IF(ISBLANK(C43),"",IF(C43=D43, "1 video",CONCATENATE((+COUNTIFS(Video_List!$C:$C,"<=" &Monitoring!F43)-COUNTIFS(Video_List!$C:$C,"<=" &Monitoring!E43))+1," videos"))) -> 1 video | K43: yes | L43: Insecta | M43: Mecoptera | N43: 0 | O43: =+IFERROR(IF(P43="#N/C","#N/C",IF(Q43=0,INDEX(Taxonomy_UniqueValues!D:D,MATCH(Q43,Taxonomy_UniqueValues!F:F,0)),INDEX(Taxonomy_UniqueValues!D:D,MATCH(P43,Taxonomy_UniqueValues!E:E,0)))),"#N/C") -> 0 | P43: Panorpoidea | Q43: Panorpidae | R43: 0 | S43: Panorpa | T43: #N/C
A44: 43 | B44: 44390 | C44: 2021-07-13_09-59-46 | D44: 2021-07-13_09-59-46 | E44: 44390.417 | F44: 44390.417 | G44: =F44-E44 -> 0.00010416666 | H44: ? | I44: ? | J44: =IF(ISBLANK(C44),"",IF(C44=D44, "1 video",CONCATENATE((+COUNTIFS(Video_List!$C:$C,"<=" &Monitoring!F44)-COUNTIFS(Video_List!$C:$C,"<=" &Monitoring!E44))+1," videos"))) -> 1 video | K44: no | L44: Insecta | M44: Diptera | N44: Brachycera | O44: =+IFERROR(IF(P44="#N/C","#N/C",IF(Q44=0,INDEX(Taxonomy_UniqueValues!D:D,MATCH(Q44,Taxonomy_UniqueValues!F:F,0)),INDEX(Taxonomy_UniqueValues!D:D,MATCH(P44,Taxonomy_UniqueValues!E:E,0)))),"#N/C") -> Muscomorpha | P44: Syrphoidea | Q44: Syrphidae | R44: Syrphinae | S44: #N/C | T44: #N/C
A45: 44 | B45: 44390 | C45: 2021-07-13_10-25-07 | D45: 2021-07-13_10-25-07 | E45: 44390.434 | F45: 44390.434 | G45: =F45-E45 -> 0.00012731482 | H45: yes | I45: exit | J45: =IF(ISBLANK(C45),"",IF(C45=D45, "1 video",CONCATENATE((+COUNTIFS(Video_List!$C:$C,"<=" &Monitoring!F45)-COUNTIFS(Video_List!$C:$C,"<=" &Monitoring!E45))+1," videos"))) -> 1 video | K45: no | L45: Insecta | M45: Diptera | N45: Brachycera | O45: =+IFERROR(IF(P45="#N/C","#N/C",IF(Q45=0,INDEX(Taxonomy_UniqueValues!D:D,MATCH(Q45,Taxonomy_UniqueValues!F:F,0)),INDEX(Taxonomy_UniqueValues!D:D,MATCH(P45,Taxonomy_UniqueValues!E:E,0)))),"#N/C") -> #N/C | P45: #N/C | Q45: #N/C | R45: #N/C | S45: #N/C | T45: #N/C
A46: 45 | B46: 44390 | C46: 2021-07-13_11-03-36 | D46: 2021-07-13_11-50-47 | E46: 44390.461 | F46: 44390.504 | G46: =F46-E46 -> 0.042858796 | H46: no | I46: entrance | J46: =IF(ISBLANK(C46),"",IF(C46=D46, "1 video",CONCATENATE((+COUNTIFS(Video_List!$C:$C,"<=" &Monitoring!F46)-COUNTIFS(Video_List!$C:$C,"<=" &Monitoring!E46))+1," videos"))) -> 4 videos | K46: no | L46: Insecta | M46: Hymenoptera | N46: Apocrita | O46: =+IFERROR(IF(P46="#N/C","#N/C",IF(Q46=0,INDEX(Taxonomy_UniqueValues!D:D,MATCH(Q46,Taxonomy_UniqueValues!F:F,0)),INDEX(Taxonomy_UniqueValues!D:D,MATCH(P46,Taxonomy_UniqueValues!E:E,0)))),"#N/C") -> Aculeata | P46: =+IFERROR(IF(Q46="#N/C","#N/C",INDEX(Taxonomy_UniqueValues!E:E,MATCH(Q46,Taxonomy_UniqueValues!F:F,0))),"#N/C") -> Formicoidea | Q46: =+IFERROR(IF(R46="#N/C","#N/C",INDEX(Taxonomy_UniqueValues!F:F,MATCH(R46,Taxonomy_UniqueValues!G:G,0))),"#N/C") -> Formicidae | R46: Formicinae | S46: #N/C | T46: #N/C
A47: 46 | B47: 44390 | C47: 2021-07-13_11-03-36 | D47: 2021-07-13_11-11-57 | E47: 44390.466 | F47: 44390.467 | G47: =F47-E47 -> 0.00047453704 | H47: no | I47: exit | J47: =IF(ISBLANK(C47),"",IF(C47=D47, "1 video",CONCATENATE((+COUNTIFS(Video_List!$C:$C,"<=" &Monitoring!F47)-COUNTIFS(Video_List!$C:$C,"<=" &Monitoring!E47))+1," videos"))) -> 2 videos | K47: no | L47: Insecta | M47: Orthoptera | N47: Caelifera | O47: =+IFERROR(IF(P47="#N/C","#N/C",IF(Q47=0,INDEX(Taxonomy_UniqueValues!D:D,MATCH(Q47,Taxonomy_UniqueValues!F:F,0)),INDEX(Taxonomy_UniqueValues!D:D,MATCH(P47,Taxonomy_UniqueValues!E:E,0)))),"#N/C") -> Acrididea | P47: Acridoidea | Q47: Acrididae | R47: #N/C | S47: #N/C | T47: #N/C
A48: 47 | B48: 44390 | C48: 2021-07-13_11-11-57 | D48: 2021-07-13_11-50-47 | E48: 44390.491 | F48: 44390.497 | G48: =F48-E48 -> 0.0058449074 | H48: no | I48: exit | J48: =IF(ISBLANK(C48),"",IF(C48=D48, "1 video",CONCATENATE((+COUNTIFS(Video_List!$C:$C,"<=" &Monitoring!F48)-COUNTIFS(Video_List!$C:$C,"<=" &Monitoring!E48))+1," videos"))) -> 3 videos | K48: yes | L48: Insecta | M48: Coleoptera | N48: Polyphaga | O48: =+IFERROR(IF(P48="#N/C","#N/C",IF(Q48=0,INDEX(Taxonomy_UniqueValues!D:D,MATCH(Q48,Taxonomy_UniqueValues!F:F,0)),INDEX(Taxonomy_UniqueValues!D:D,MATCH(P48,Taxonomy_UniqueValues!E:E,0)))),"#N/C") -> Cucujiformia | P48: Coccinelloidea | Q48: Coccinellidae | R48: Coccinellinae | S48: Psyllobora | T48: vigintiduopunctata
A49: 48 | B49: 44390 | C49: 2021-07-13_12-22-04 | D49: 2021-07-13_12-22-04 | E49: 44390.515 | F49: 44390.515 | G49: =F49-E49 -> 8.1018516e-05 | H49: yes | I49: exit | J49: =IF(ISBLANK(C49),"",IF(C49=D49, "1 video",CONCATENATE((+COUNTIFS(Video_List!$C:$C,"<=" &Monitoring!F49)-COUNTIFS(Video_List!$C:$C,"<=" &Monitoring!E49))+1," videos"))) -> 1 video | K49: no | L49: Insecta | M49: Diptera | N49: Brachycera | O49: =+IFERROR(IF(P49="#N/C","#N/C",IF(Q49=0,INDEX(Taxonomy_UniqueValues!D:D,MATCH(Q49,Taxonomy_UniqueValues!F:F,0)),INDEX(Taxonomy_UniqueValues!D:D,MATCH(P49,Taxonomy_UniqueValues!E:E,0)))),"#N/C") -> #N/C | P49: #N/C | Q49: #N/C | R49: #N/C | S49: #N/C | T49: #N/C
A50: 49 | B50: 44390 | C50: 2021-07-13_12-26-42 | D50: 2021-07-13_12-26-42 | E50: 44390.519 | F50: 44390.519 | G50: =F50-E50 -> 4.62963e-05 | H50: yes | I50: exit | J50: =IF(ISBLANK(C50),"",IF(C50=D50, "1 video",CONCATENATE((+COUNTIFS(Video_List!$C:$C,"<=" &Monitoring!F50)-COUNTIFS(Video_List!$C:$C,"<=" &Monitoring!E50))+1," videos"))) -> 1 video | K50: yes | L50: Insecta | M50: Hymenoptera | N50: Apocrita | O50: =+IFERROR(IF(P50="#N/C","#N/C",IF(Q50=0,INDEX(Taxonomy_UniqueValues!D:D,MATCH(Q50,Taxonomy_UniqueValues!F:F,0)),INDEX(Taxonomy_UniqueValues!D:D,MATCH(P50,Taxonomy_UniqueValues!E:E,0)))),"#N/C") -> Aculeata | P50: Apoidea | Q50: Apidae | R50: Apinae | S50: Bombus | T50: #N/C
A51: 50 | B51: 44390 | C51: 2021-07-13_12-39-07 | D51: 2021-07-13_12-39-07 | E51: 44390.527 | F51: 44390.527 | G51: =F51-E51 -> 5.7870369e-05 | H51: no | I51: exit | J51: =IF(ISBLANK(C51),"",IF(C51=D51, "1 video",CONCATENATE((+COUNTIFS(Video_List!$C:$C,"<=" &Monitoring!F51)-COUNTIFS(Video_List!$C:$C,"<=" &Monitoring!E51))+1," videos"))) -> 1 video | K51: yes | L51: Insecta | M51: Hymenoptera | N51: Apocrita | O51: =+IFERROR(IF(P51="#N/C","#N/C",IF(Q51=0,INDEX(Taxonomy_UniqueValues!D:D,MATCH(Q51,Taxonomy_UniqueValues!F:F,0)),INDEX(Taxonomy_UniqueValues!D:D,MATCH(P51,Taxonomy_UniqueValues!E:E,0)))),"#N/C") -> Parasitica | P51: Ichneumonoidea | Q51: Ichneumonidae | R51: Pimplinae | S51: Pimpla | T51: rufipes
A52: 51 | B52: 44390 | C52: 2021-07-13_13-07-11 | D52: 2021-07-13_13-07-11 | E52: 44390.547 | F52: 44390.547 | G52: =F52-E52 -> 4.62963e-05 | H52: ? | I52: ? | J52: =IF(ISBLANK(C52),"",IF(C52=D52, "1 video",CONCATENATE((+COUNTIFS(Video_List!$C:$C,"<=" &Monitoring!F52)-COUNTIFS(Video_List!$C:$C,"<=" &Monitoring!E52))+1," videos"))) -> 1 video | K52: no | L52: Insecta | M52: Diptera | N52: Brachycera | O52: =+IFERROR(IF(P52="#N/C","#N/C",IF(Q52=0,INDEX(Taxonomy_UniqueValues!D:D,MATCH(Q52,Taxonomy_UniqueValues!F:F,0)),INDEX(Taxonomy_UniqueValues!D:D,MATCH(P52,Taxonomy_UniqueValues!E:E,0)))),"#N/C") -> #N/C | P52: #N/C | Q52: #N/C | R52: #N/C | S52: #N/C | T52: #N/C
A53: 52 | B53: 44390 | C53: 2021-07-13_13-20-39 | D53: 2021-07-13_13-20-39 | E53: 44390.556 | F53: 44390.556 | G53: =F53-E53 -> 0.00011574074 | H53: yes | I53: exit | J53: =IF(ISBLANK(C53),"",IF(C53=D53, "1 video",CONCATENATE((+COUNTIFS(Video_List!$C:$C,"<=" &Monitoring!F53)-COUNTIFS(Video_List!$C:$C,"<=" &Monitoring!E53))+1," videos"))) -> 1 video | K53: no | L53: Insecta | M53: Diptera | N53: Brachycera | O53: =+IFERROR(IF(P53="#N/C","#N/C",IF(Q53=0,INDEX(Taxonomy_UniqueValues!D:D,MATCH(Q53,Taxonomy_UniqueValues!F:F,0)),INDEX(Taxonomy_UniqueValues!D:D,MATCH(P53,Taxonomy_UniqueValues!E:E,0)))),"#N/C") -> #N/C | P53: #N/C | Q53: #N/C | R53: #N/C | S53: #N/C | T53: #N/C
A54: 53 | B54: 44390 | C54: 2021-07-13_13-27-31 | D54: 2021-07-13_14-25-46 | E54: 44390.561 | F54: 44390.601 | G54: =F54-E54 -> 0.040706019 | H54: ? | I54: ? | J54: =IF(ISBLANK(C54),"",IF(C54=D54, "1 video",CONCATENATE((+COUNTIFS(Video_List!$C:$C,"<=" &Monitoring!F54)-COUNTIFS(Video_List!$C:$C,"<=" &Monitoring!E54))+1," videos"))) -> 5 videos | K54: yes | L54: Insecta | M54: Coleoptera | N54: Polyphaga | O54: =+IFERROR(IF(P54="#N/C","#N/C",IF(Q54=0,INDEX(Taxonomy_UniqueValues!D:D,MATCH(Q54,Taxonomy_UniqueValues!F:F,0)),INDEX(Taxonomy_UniqueValues!D:D,MATCH(P54,Taxonomy_UniqueValues!E:E,0)))),"#N/C") -> Cucujiformia | P54: Tenebrionoidea | Q54: Oedemeridae | R54: Nacerdinae | S54: Chrysanthia | T54: viridissima
A55: 54 | B55: 44390 | C55: 2021-07-13_14-17-56 | D55: 2021-07-13_14-17-56 | E55: 44390.596 | F55: 44390.596 | G55: =F55-E55 -> 1.1574077e-05 | H55: yes | I55: exit | J55: =IF(ISBLANK(C55),"",IF(C55=D55, "1 video",CONCATENATE((+COUNTIFS(Video_List!$C:$C,"<=" &Monitoring!F55)-COUNTIFS(Video_List!$C:$C,"<=" &Monitoring!E55))+1," videos"))) -> 1 video | K55: no | L55: Insecta | M55: Diptera | N55: Brachycera | O55: =+IFERROR(IF(P55="#N/C","#N/C",IF(Q55=0,INDEX(Taxonomy_UniqueValues!D:D,MATCH(Q55,Taxonomy_UniqueValues!F:F,0)),INDEX(Taxonomy_UniqueValues!D:D,MATCH(P55,Taxonomy_UniqueValues!E:E,0)))),"#N/C") -> Asilomorpha | P55: Asiloidea | Q55: Asilidae | R55: Asilinae | S55: Tolmerus | T55: #N/C
A56: 55 | B56: 44390 | C56: 2021-07-13_14-24-21 | D56: 2021-07-13_14-25-46 | E56: 44390.6 | F56: 44390.601 | G56: =F56-E56 -> 0.0012268519 | H56: yes | I56: exit | J56: =IF(ISBLANK(C56),"",IF(C56=D56, "1 video",CONCATENATE((+COUNTIFS(Video_List!$C:$C,"<=" &Monitoring!F56)-COUNTIFS(Video_List!$C:$C,"<=" &Monitoring!E56))+1," videos"))) -> 2 videos | K56: no | L56: Insecta | M56: Diptera | N56: Brachycera | O56: =+IFERROR(IF(P56="#N/C","#N/C",IF(Q56=0,INDEX(Taxonomy_UniqueValues!D:D,MATCH(Q56,Taxonomy_UniqueValues!F:F,0)),INDEX(Taxonomy_UniqueValues!D:D,MATCH(P56,Taxonomy_UniqueValues!E:E,0)))),"#N/C") -> Asilomorpha | P56: Asiloidea | Q56: Asilidae | R56: Asilinae | S56: #N/C | T56: #N/C
A57: 56 | B57: 44390 | C57: 2021-07-13_14-30-25 | D57: 2021-07-13_14-30-25 | E57: 44390.604 | F57: 44390.605 | G57: =F57-E57 -> 0.00016203704 | H57: ? | I57: exit | J57: =IF(ISBLANK(C57),"",IF(C57=D57, "1 video",CONCATENATE((+COUNTIFS(Video_List!$C:$C,"<=" &Monitoring!F57)-COUNTIFS(Video_List!$C:$C,"<=" &Monitoring!E57))+1," videos"))) -> 1 video | K57: no | L57: Insecta | M57: Diptera | N57: Brachycera | O57: =+IFERROR(IF(P57="#N/C","#N/C",IF(Q57=0,INDEX(Taxonomy_UniqueValues!D:D,MATCH(Q57,Taxonomy_UniqueValues!F:F,0)),INDEX(Taxonomy_UniqueValues!D:D,MATCH(P57,Taxonomy_UniqueValues!E:E,0)))),"#N/C") -> Asilomorpha | P57: Asiloidea | Q57: Asilidae | R57: Asilinae | S57: #N/C | T57: #N/C
A58: 57 | B58: 44390 | C58: 2021-07-13_14-38-42 | D58: 2021-07-13_14-46-17 | E58: 44390.61 | F58: 44390.616 | G58: =F58-E58 -> 0.0053587963 | H58: yes | I58: exit | J58: =IF(ISBLANK(C58),"",IF(C58=D58, "1 video",CONCATENATE((+COUNTIFS(Video_List!$C:$C,"<=" &Monitoring!F58)-COUNTIFS(Video_List!$C:$C,"<=" &Monitoring!E58))+1," videos"))) -> 5 videos | K58: no | L58: Insecta | M58: Diptera | N58: Brachycera | O58: =+IFERROR(IF(P58="#N/C","#N/C",IF(Q58=0,INDEX(Taxonomy_UniqueValues!D:D,MATCH(Q58,Taxonomy_UniqueValues!F:F,0)),INDEX(Taxonomy_UniqueValues!D:D,MATCH(P58,Taxonomy_UniqueValues!E:E,0)))),"#N/C") -> #N/C | P58: #N/C | Q58: #N/C | R58: #N/C | S58: #N/C | T58: #N/C
... A73: 72 | B73: 44390 | C73: 2021-07-13_16-57-08 | D73: 2021-07-13_16-57-08 | E73: 44390.707 | F73: 44390.707 | G73: =F73-E73 -> 0.00017361111 | H73: ? | I73: ? | J73: =IF(ISBLANK(C73),"",IF(C73=D73, "1 video",CONCATENATE((+COUNTIFS(Video_List!$C:$C,"<=" &Monitoring!F73)-COUNTIFS(Video_List!$C:$C,"<=" &Monitoring!E73))+1," videos"))) -> 1 video | K73: no | L73: Insecta | M73: Orthoptera | N73: Caelifera | O73: =+IFERROR(IF(P73="#N/C","#N/C",IF(Q73=0,INDEX(Taxonomy_UniqueValues!D:D,MATCH(Q73,Taxonomy_UniqueValues!F:F,0)),INDEX(Taxonomy_UniqueValues!D:D,MATCH(P73,Taxonomy_UniqueValues!E:E,0)))),"#N/C") -> Acrididea | P73: Acridoidea | Q73: Acrididae | R73: Gomphocerinae | S73: Chorthippus | T73: #N/C
A74: 73 | B74: 44390 | C74: 2021-07-13_16-57-08 | D74: 2021-07-13_16-57-08 | E74: 44390.707 | F74: 44390.707 | G74: =F74-E74 -> 1.1574077e-05 | H74: yes | I74: exit | J74: =IF(ISBLANK(C74),"",IF(C74=D74, "1 video",CONCATENATE((+COUNTIFS(Video_List!$C:$C,"<=" &Monitoring!F74)-COUNTIFS(Video_List!$C:$C,"<=" &Monitoring!E74))+1," videos"))) -> 1 video | K74: yes | L74: Insecta | M74: Diptera | N74: Brachycera | O74: =+IFERROR(IF(P74="#N/C","#N/C",IF(Q74=0,INDEX(Taxonomy_UniqueValues!D:D,MATCH(Q74,Taxonomy_UniqueValues!F:F,0)),INDEX(Taxonomy_UniqueValues!D:D,MATCH(P74,Taxonomy_UniqueValues!E:E,0)))),"#N/C") -> Muscomorpha | P74: Muscoidea | Q74: Fanniidae | R74: 0 | S74: Fannia | T74: #N/C
A75: 74 | B75: 44390 | C75: 2021-07-13_17-10-39 | D75: 2021-07-13_17-10-39 | E75: 44390.716 | F75: 44390.716 | G75: =F75-E75 -> 5.7870369e-05 | H75: ? | I75: ? | J75: =IF(ISBLANK(C75),"",IF(C75=D75, "1 video",CONCATENATE((+COUNTIFS(Video_List!$C:$C,"<=" &Monitoring!F75)-COUNTIFS(Video_List!$C:$C,"<=" &Monitoring!E75))+1," videos"))) -> 1 video | K75: yes | L75: =+IFERROR(IF(M75="#N/C","#N/C",INDEX(Taxonomy_UniqueValues!A:A,MATCH(M75,Taxonomy_UniqueValues!B:B,0))),"#N/C") -> Insecta | M75: =+IFERROR(IF(N75="#N/C","#N/C",INDEX(Taxonomy_UniqueValues!B:B,MATCH(N75,Taxonomy_UniqueValues!C:C,0))),"#N/C") -> Hymenoptera | N75: =+IFERROR(IF(O75="#N/C","#N/C",INDEX(Taxonomy_UniqueValues!C:C,MATCH(O75,Taxonomy_UniqueValues!D:D,0))),"#N/C") -> Apocrita | O75: =+IFERROR(IF(P75="#N/C","#N/C",INDEX(Taxonomy_UniqueValues!D:D,MATCH(P75,Taxonomy_UniqueValues!E:E,0))),"#N/C") -> Aculeata | P75: =+IFERROR(IF(Q75="#N/C","#N/C",INDEX(Taxonomy_UniqueValues!E:E,MATCH(Q75,Taxonomy_UniqueValues!F:F,0))),"#N/C") -> Formicoidea | Q75: =+IFERROR(IF(R75="#N/C","#N/C",INDEX(Taxonomy_UniqueValues!F:F,MATCH(R75,Taxonomy_UniqueValues!G:G,0))),"#N/C") -> Formicidae | R75: =+IFERROR(IF(S75="#N/C","#N/C",INDEX(Taxonomy_UniqueValues!G:G,MATCH(S75,Taxonomy_UniqueValues!H:H,0))),"#N/C") -> Formicinae | S75: Lasius | T75: fuliginosus
A76: 75 | B76: 44390 | C76: 2021-07-13_17-13-55 | D76: 2021-07-13_17-13-55 | E76: 44390.718 | F76: 44390.718 | G76: =F76-E76 -> 4.62963e-05 | H76: ? | I76: ? | J76: =IF(ISBLANK(C76),"",IF(C76=D76, "1 video",CONCATENATE((+COUNTIFS(Video_List!$C:$C,"<=" &Monitoring!F76)-COUNTIFS(Video_List!$C:$C,"<=" &Monitoring!E76))+1," videos"))) -> 1 video | K76: no | L76: Insecta | M76: Diptera | N76: Brachycera | O76: =+IFERROR(IF(P76="#N/C","#N/C",IF(Q76=0,INDEX(Taxonomy_UniqueValues!D:D,MATCH(Q76,Taxonomy_UniqueValues!F:F,0)),INDEX(Taxonomy_UniqueValues!D:D,MATCH(P76,Taxonomy_UniqueValues!E:E,0)))),"#N/C") -> Muscomorpha | P76: Syrphoidea | Q76: Syrphidae | R76: Syrphinae | S76: Melanostoma | T76: #N/C
A77: 76 | B77: 44390 | C77: 2021-07-13_17-32-05 | D77: 2021-07-13_17-32-05 | E77: 44390.731 | F77: 44390.731 | G77: =F77-E77 -> 9.2592592e-05 | H77: yes | I77: exit | J77: =IF(ISBLANK(C77),"",IF(C77=D77, "1 video",CONCATENATE((+COUNTIFS(Video_List!$C:$C,"<=" &Monitoring!F77)-COUNTIFS(Video_List!$C:$C,"<=" &Monitoring!E77))+1," videos"))) -> 1 video | K77: no | L77: Insecta | M77: Diptera | N77: Brachycera | O77: =+IFERROR(IF(P77="#N/C","#N/C",IF(Q77=0,INDEX(Taxonomy_UniqueValues!D:D,MATCH(Q77,Taxonomy_UniqueValues!F:F,0)),INDEX(Taxonomy_UniqueValues!D:D,MATCH(P77,Taxonomy_UniqueValues!E:E,0)))),"#N/C") -> #N/C | P77: #N/C | Q77: #N/C | R77: #N/C | S77: #N/C | T77: #N/C
A78: 77 | B78: 44390 | C78: 2021-07-13_17-45-32 | D78: 2021-07-13_17-45-32 | E78: 44390.74 | F78: 44390.74 | G78: =F78-E78 -> 4.6296293e-05 | H78: yes | I78: exit | J78: =IF(ISBLANK(C78),"",IF(C78=D78, "1 video",CONCATENATE((+COUNTIFS(Video_List!$C:$C,"<=" &Monitoring!F78)-COUNTIFS(Video_List!$C:$C,"<=" &Monitoring!E78))+1," videos"))) -> 1 video | K78: no | L78: Insecta | M78: Diptera | N78: Nematocera | O78: =+IFERROR(IF(P78="#N/C","#N/C",IF(Q78=0,INDEX(Taxonomy_UniqueValues!D:D,MATCH(Q78,Taxonomy_UniqueValues!F:F,0)),INDEX(Taxonomy_UniqueValues!D:D,MATCH(P78,Taxonomy_UniqueValues!E:E,0)))),"#N/C") -> Bibionomorpha | P78: Sciaroidea | Q78: Keroplatidae | R78: Macrocerinae | S78: Macrocera | T78: #N/C
A79: 78 | B79: 44390 | C79: 2021-07-13_17-56-52 | D79: 2021-07-13_17-56-52 | E79: 44390.748 | F79: 44390.748 | G79: =F79-E79 -> 9.2592592e-05 | H79: yes | I79: exit | J79: =IF(ISBLANK(C79),"",IF(C79=D79, "1 video",CONCATENATE((+COUNTIFS(Video_List!$C:$C,"<=" &Monitoring!F79)-COUNTIFS(Video_List!$C:$C,"<=" &Monitoring!E79))+1," videos"))) -> 1 video | K79: no | L79: Insecta | M79: Diptera | N79: Brachycera | O79: =+IFERROR(IF(P79="#N/C","#N/C",IF(Q79=0,INDEX(Taxonomy_UniqueValues!D:D,MATCH(Q79,Taxonomy_UniqueValues!F:F,0)),INDEX(Taxonomy_UniqueValues!D:D,MATCH(P79,Taxonomy_UniqueValues!E:E,0)))),"#N/C") -> #N/C | P79: #N/C | Q79: #N/C | R79: #N/C | S79: #N/C | T79: #N/C
A80: 79 | B80: 44390 | C80: 2021-07-13_17-59-20 | D80: 2021-07-13_17-59-20 | E80: 44390.75 | F80: 44390.75 | G80: =F80-E80 -> 6.9444446e-05 | H80: yes | I80: exit | J80: =IF(ISBLANK(C80),"",IF(C80=D80, "1 video",CONCATENATE((+COUNTIFS(Video_List!$C:$C,"<=" &Monitoring!F80)-COUNTIFS(Video_List!$C:$C,"<=" &Monitoring!E80))+1," videos"))) -> 1 video | K80: no | L80: Insecta | M80: Diptera | N80: Brachycera | O80: =+IFERROR(IF(P80="#N/C","#N/C",IF(Q80=0,INDEX(Taxonomy_UniqueValues!D:D,MATCH(Q80,Taxonomy_UniqueValues!F:F,0)),INDEX(Taxonomy_UniqueValues!D:D,MATCH(P80,Taxonomy_UniqueValues!E:E,0)))),"#N/C") -> #N/C | P80: #N/C | Q80: #N/C | R80: #N/C | S80: #N/C | T80: #N/C
A81: 80 | B81: 44390 | C81: 2021-07-13_18-03-08 | D81: 2021-07-13_18-03-08 | E81: 44390.752 | F81: 44390.752 | G81: =F81-E81 -> 0.00010416667 | H81: yes | I81: exit | J81: =IF(ISBLANK(C81),"",IF(C81=D81, "1 video",CONCATENATE((+COUNTIFS(Video_List!$C:$C,"<=" &Monitoring!F81)-COUNTIFS(Video_List!$C:$C,"<=" &Monitoring!E81))+1," videos"))) -> 1 video | K81: no | L81: Insecta | M81: Diptera | N81: Brachycera | O81: =+IFERROR(IF(P81="#N/C","#N/C",IF(Q81=0,INDEX(Taxonomy_UniqueValues!D:D,MATCH(Q81,Taxonomy_UniqueValues!F:F,0)),INDEX(Taxonomy_UniqueValues!D:D,MATCH(P81,Taxonomy_UniqueValues!E:E,0)))),"#N/C") -> #N/C | P81: #N/C | Q81: #N/C | R81: #N/C | S81: #N/C | T81: #N/C
...

Sheet Taxonomy_UniqueValues
A1: Class | B1: Order | C1: Suborder | D1: Infraorder | E1: Superfamily | F1: Family | G1: Subfamily | H1: Genus | I1: Species | K1: Key
A2: #N/C | B2: #N/C | C2: #N/C | D2: =+IFERROR(IF(E2="#N/C","#N/C",INDEX([1]ClassificationClasses!D:D,MATCH(E2,[1]ClassificationClasses!E:E,0))),"ERROR") -> #N/C | E2: #N/C | F2: #N/C | G2: #N/C | H2: #N/C | I2: #N/C | J2: {=_xlfn.LET(_xlpm.cls,A2, _xlpm.ord,IFERROR(B2,"#N/C"), _xlpm.subord,IFERROR(C2,"#N/C"), _xlpm.infr,IFERROR(D2,"#N/C"), _xlpm.sf,IFERROR(E2,"#N/C"), _xlpm.fam,IFERROR(F2,"#N/C"), _xlpm.subfam,IF(TRIM(G2)="-","#N/C",IFERROR(G2,"#N/C")), _xlpm.subfamMatch,IFERROR(_xlfn._xlws.FILTER(ClassificationClasses[Classification Class],(ClassificationClasses[Class]=_xlpm.cls)*(ClassificationClasses[Order]=_xlpm.ord)*(ClassificationClasses[Suborder]=_xlpm.subord)*(ClassificationClasses[Infraorder]=_xlpm.infr)*(ClassificationClasses[Superfamily]=_xlpm.sf)*(ClassificationClasses[Family]=_xlpm.fam)*(ClassificationClasses[Subfamily]=_xlpm.subfam),""),""), _xlpm.uniqueSubfam,IF(_xlpm.subfamMatch="","",_xlfn.UNIQUE(_xlpm.subfamMatch)), _xlpm.numUniqueSubfam,IF(_xlpm.uniqueSubfam="",0,ROWS(_xlpm.uniqueSubfam)), _xlpm.resultSubfam,IF(_xlpm.numUniqueSubfam=1,INDEX(_xlpm.uniqueSubfam,1),IF(_xlpm.numUniqueSubfam>=1,_xlpm.subfam,"")), _xlpm.famMatch,IFERROR(_xlfn._xlws.FILTER(ClassificationClasses[Classification Class],(ClassificationClasses[Class]=_xlpm.cls)*(ClassificationClasses[Order]=_xlpm.ord)*(ClassificationClasses[Suborder]=_xlpm.subord)*(ClassificationClasses[Infraorder]=_xlpm.infr)*(ClassificationClasses[Superfamily]=_xlpm.sf)*(ClassificationClasses[Family]=_xlpm.fam),""),""), _xlpm.uniqueFam,IF(_xlpm.famMatch="","",_xlfn.UNIQUE(_xlpm.famMatch)), _xlpm.numUniqueFam,IF(_xlpm.uniqueFam="",0,ROWS(_xlpm.uniqueFam)), _xlpm.resultFam,IF(_xlpm.numUniqueFam=1,INDEX(_xlpm.uniqueFam,1),IF(_xlpm.numUniqueFam>=1,_xlpm.fam,"")), _xlpm.sfMatch,IFERROR(_xlfn._xlws.FILTER(ClassificationClasses[Classification Class],(ClassificationClasses[Class]=_xlpm.cls)*(ClassificationClasses[Order]=_xlpm.ord)*(ClassificationClasses[Suborder]=_xlpm.subord)*(ClassificationClasses[Infraorder]=_xlpm.infr)*(ClassificationClasses[Superfamily]=_xlpm.sf),""),""), _xlpm.uniqueSf,IF(_xlpm.sfMatch="","",_xlfn.UNIQUE(_xlpm.sfMatch)), _xlpm.numUniqueSf,IF(_xlpm.uniqueSf="",0,ROWS(_xlpm.uniqueSf)), _xlpm.resultSf,IF(_xlpm.numUniqueSf=1,INDEX(_xlpm.uniqueSf,1),IF(_xlpm.numUniqueSf>=1,_xlpm.sf,"")), _xlpm.computedResult,IF(AND(_xlpm.fam="#N/C",_xlpm.subfam="#N/C"),_xlpm.sf,IF(_xlpm.resultSubfam<>"",_xlpm.resultSubfam,IF(_xlpm.resultFam<>"",_xlpm.resultFam,IF(_xlpm.resultSf<>"",_xlpm.resultSf,"")))), _xlpm.fallback,IF(IFERROR(B2,"#N/C")="#N/C",A2,IF(IFERROR(C2,"#N/C")="#N/C",B2,IF(IFERROR(D2,"#N/C")="#N/C",C2,IF(IFERROR(E2,"#N/C")="#N/C",D2,IF(IFERROR(F2,"#N/C")="#N/C",E2,IF(IFERROR(G2,"#N/C")="#N/C",F2,"#N/C")))))), _xlpm.finalResult,IF(OR(_xlpm.computedResult="",_xlpm.computedResult="#N/C"),_xlpm.fallback,_xlpm.computedResult), INDEX(_xlpm.finalResult,1))} -> #N/C | K2: =+CONCATENATE(A2,".",B2,".",C2,".",D2,".",E2,".",F2,".",G2,".",H2,".",I2) -> #N/C.#N/C.#N/C.#N/C.#N/C.#N/C.#N/C.#N/C.#N/C | L2: =+COUNTIF([1]Monitoring!AN:AN,K2) -> 79
A3: Arachnida | B3: Araneae | C3: Arneomorphae | D3: =+IFERROR(IF(E3="#N/C","#N/C",INDEX([1]ClassificationClasses!D:D,MATCH(E3,[1]ClassificationClasses!E:E,0))),"ERROR") -> Araneomorphae | E3: Araneoidea | F3: #N/C | G3: #N/C | H3: #N/C | I3: #N/C | J3: {=_xlfn.LET(_xlpm.cls,A3, _xlpm.ord,IFERROR(B3,"#N/C"), _xlpm.subord,IFERROR(C3,"#N/C"), _xlpm.infr,IFERROR(D3,"#N/C"), _xlpm.sf,IFERROR(E3,"#N/C"), _xlpm.fam,IFERROR(F3,"#N/C"), _xlpm.subfam,IF(TRIM(G3)="-","#N/C",IFERROR(G3,"#N/C")), _xlpm.subfamMatch,IFERROR(_xlfn._xlws.FILTER(ClassificationClasses[Classification Class],(ClassificationClasses[Class]=_xlpm.cls)*(ClassificationClasses[Order]=_xlpm.ord)*(ClassificationClasses[Suborder]=_xlpm.subord)*(ClassificationClasses[Infraorder]=_xlpm.infr)*(ClassificationClasses[Superfamily]=_xlpm.sf)*(ClassificationClasses[Family]=_xlpm.fam)*(ClassificationClasses[Subfamily]=_xlpm.subfam),""),""), _xlpm.uniqueSubfam,IF(_xlpm.subfamMatch="","",_xlfn.UNIQUE(_xlpm.subfamMatch)), _xlpm.numUniqueSubfam,IF(_xlpm.uniqueSubfam="",0,ROWS(_xlpm.uniqueSubfam)), _xlpm.resultSubfam,IF(_xlpm.numUniqueSubfam=1,INDEX(_xlpm.uniqueSubfam,1),IF(_xlpm.numUniqueSubfam>=1,_xlpm.subfam,"")), _xlpm.famMatch,IFERROR(_xlfn._xlws.FILTER(ClassificationClasses[Classification Class],(ClassificationClasses[Class]=_xlpm.cls)*(ClassificationClasses[Order]=_xlpm.ord)*(ClassificationClasses[Suborder]=_xlpm.subord)*(ClassificationClasses[Infraorder]=_xlpm.infr)*(ClassificationClasses[Superfamily]=_xlpm.sf)*(ClassificationClasses[Family]=_xlpm.fam),""),""), _xlpm.uniqueFam,IF(_xlpm.famMatch="","",_xlfn.UNIQUE(_xlpm.famMatch)), _xlpm.numUniqueFam,IF(_xlpm.uniqueFam="",0,ROWS(_xlpm.uniqueFam)), _xlpm.resultFam,IF(_xlpm.numUniqueFam=1,INDEX(_xlpm.uniqueFam,1),IF(_xlpm.numUniqueFam>=1,_xlpm.fam,"")), _xlpm.sfMatch,IFERROR(_xlfn._xlws.FILTER(ClassificationClasses[Classification Class],(ClassificationClasses[Class]=_xlpm.cls)*(ClassificationClasses[Order]=_xlpm.ord)*(ClassificationClasses[Suborder]=_xlpm.subord)*(ClassificationClasses[Infraorder]=_xlpm.infr)*(ClassificationClasses[Superfamily]=_xlpm.sf),""),""), _xlpm.uniqueSf,IF(_xlpm.sfMatch="","",_xlfn.UNIQUE(_xlpm.sfMatch)), _xlpm.numUniqueSf,IF(_xlpm.uniqueSf="",0,ROWS(_xlpm.uniqueSf)), _xlpm.resultSf,IF(_xlpm.numUniqueSf=1,INDEX(_xlpm.uniqueSf,1),IF(_xlpm.numUniqueSf>=1,_xlpm.sf,"")), _xlpm.computedResult,IF(AND(_xlpm.fam="#N/C",_xlpm.subfam="#N/C"),_xlpm.sf,IF(_xlpm.resultSubfam<>"",_xlpm.resultSubfam,IF(_xlpm.resultFam<>"",_xlpm.resultFam,IF(_xlpm.resultSf<>"",_xlpm.resultSf,"")))), _xlpm.fallback,IF(IFERROR(B3,"#N/C")="#N/C",A3,IF(IFERROR(C3,"#N/C")="#N/C",B3,IF(IFERROR(D3,"#N/C")="#N/C",C3,IF(IFERROR(E3,"#N/C")="#N/C",D3,IF(IFERROR(F3,"#N/C")="#N/C",E3,IF(IFERROR(G3,"#N/C")="#N/C",F3,"#N/C")))))), _xlpm.finalResult,IF(OR(_xlpm.computedResult="",_xlpm.computedResult="#N/C"),_xlpm.fallback,_xlpm.computedResult), INDEX(_xlpm.finalResult,1))} -> Araneoidea | K3: =+CONCATENATE(A3,".",B3,".",C3,".",D3,".",E3,".",F3,".",G3,".",H3,".",I3) -> Arachnida.Araneae.Arneomorphae.Araneomorphae.Araneoidea.#N/C.#N/C.#N/C.#N/C | L3: =+COUNTIF([1]Monitoring!AN:AN,K3) -> 3
A4: Arachnida | B4: Araneae | C4: Arneomorphae | D4: =+IFERROR(IF(E4="#N/C","#N/C",INDEX([1]ClassificationClasses!D:D,MATCH(E4,[1]ClassificationClasses!E:E,0))),"ERROR") -> Araneomorphae | E4: Araneoidea | F4: Araneidae | G4: Araneinae | H4: #N/C | I4: #N/C | J4: {=_xlfn.LET(_xlpm.cls,A4, _xlpm.ord,IFERROR(B4,"#N/C"), _xlpm.subord,IFERROR(C4,"#N/C"), _xlpm.infr,IFERROR(D4,"#N/C"), _xlpm.sf,IFERROR(E4,"#N/C"), _xlpm.fam,IFERROR(F4,"#N/C"), _xlpm.subfam,IF(TRIM(G4)="-","#N/C",IFERROR(G4,"#N/C")), _xlpm.subfamMatch,IFERROR(_xlfn._xlws.FILTER(ClassificationClasses[Classification Class],(ClassificationClasses[Class]=_xlpm.cls)*(ClassificationClasses[Order]=_xlpm.ord)*(ClassificationClasses[Suborder]=_xlpm.subord)*(ClassificationClasses[Infraorder]=_xlpm.infr)*(ClassificationClasses[Superfamily]=_xlpm.sf)*(ClassificationClasses[Family]=_xlpm.fam)*(ClassificationClasses[Subfamily]=_xlpm.subfam),""),""), _xlpm.uniqueSubfam,IF(_xlpm.subfamMatch="","",_xlfn.UNIQUE(_xlpm.subfamMatch)), _xlpm.numUniqueSubfam,IF(_xlpm.uniqueSubfam="",0,ROWS(_xlpm.uniqueSubfam)), _xlpm.resultSubfam,IF(_xlpm.numUniqueSubfam=1,INDEX(_xlpm.uniqueSubfam,1),IF(_xlpm.numUniqueSubfam>=1,_xlpm.subfam,"")), _xlpm.famMatch,IFERROR(_xlfn._xlws.FILTER(ClassificationClasses[Classification Class],(ClassificationClasses[Class]=_xlpm.cls)*(ClassificationClasses[Order]=_xlpm.ord)*(ClassificationClasses[Suborder]=_xlpm.subord)*(ClassificationClasses[Infraorder]=_xlpm.infr)*(ClassificationClasses[Superfamily]=_xlpm.sf)*(ClassificationClasses[Family]=_xlpm.fam),""),""), _xlpm.uniqueFam,IF(_xlpm.famMatch="","",_xlfn.UNIQUE(_xlpm.famMatch)), _xlpm.numUniqueFam,IF(_xlpm.uniqueFam="",0,ROWS(_xlpm.uniqueFam)), _xlpm.resultFam,IF(_xlpm.numUniqueFam=1,INDEX(_xlpm.uniqueFam,1),IF(_xlpm.numUniqueFam>=1,_xlpm.fam,"")), _xlpm.sfMatch,IFERROR(_xlfn._xlws.FILTER(ClassificationClasses[Classification Class],(ClassificationClasses[Class]=_xlpm.cls)*(ClassificationClasses[Order]=_xlpm.ord)*(ClassificationClasses[Suborder]=_xlpm.subord)*(ClassificationClasses[Infraorder]=_xlpm.infr)*(ClassificationClasses[Superfamily]=_xlpm.sf),""),""), _xlpm.uniqueSf,IF(_xlpm.sfMatch="","",_xlfn.UNIQUE(_xlpm.sfMatch)), _xlpm.numUniqueSf,IF(_xlpm.uniqueSf="",0,ROWS(_xlpm.uniqueSf)), _xlpm.resultSf,IF(_xlpm.numUniqueSf=1,INDEX(_xlpm.uniqueSf,1),IF(_xlpm.numUniqueSf>=1,_xlpm.sf,"")), _xlpm.computedResult,IF(AND(_xlpm.fam="#N/C",_xlpm.subfam="#N/C"),_xlpm.sf,IF(_xlpm.resultSubfam<>"",_xlpm.resultSubfam,IF(_xlpm.resultFam<>"",_xlpm.resultFam,IF(_xlpm.resultSf<>"",_xlpm.resultSf,"")))), _xlpm.fallback,IF(IFERROR(B4,"#N/C")="#N/C",A4,IF(IFERROR(C4,"#N/C")="#N/C",B4,IF(IFERROR(D4,"#N/C")="#N/C",C4,IF(IFERROR(E4,"#N/C")="#N/C",D4,IF(IFERROR(F4,"#N/C")="#N/C",E4,IF(IFERROR(G4,"#N/C")="#N/C",F4,"#N/C")))))), _xlpm.finalResult,IF(OR(_xlpm.computedResult="",_xlpm.computedResult="#N/C"),_xlpm.fallback,_xlpm.computedResult), INDEX(_xlpm.finalResult,1))} -> spider | K4: =+CONCATENATE(A4,".",B4,".",C4,".",D4,".",E4,".",F4,".",G4,".",H4,".",I4) -> Arachnida.Araneae.Arneomorphae.Araneomorphae.Araneoidea.Araneidae.Araneinae.#N/C.#N/C | L4: =+COUNTIF([1]Monitoring!AN:AN,K4) -> 2
A5: Arachnida | B5: Araneae | C5: Arneomorphae | D5: =+IFERROR(IF(E5="#N/C","#N/C",INDEX([1]ClassificationClasses!D:D,MATCH(E5,[1]ClassificationClasses!E:E,0))),"ERROR") -> Araneomorphae | E5: Araneoidea | F5: Araneidae | G5: Araneinae | H5: Araneus | I5: #N/C | J5: {=_xlfn.LET(_xlpm.cls,A5, _xlpm.ord,IFERROR(B5,"#N/C"), _xlpm.subord,IFERROR(C5,"#N/C"), _xlpm.infr,IFERROR(D5,"#N/C"), _xlpm.sf,IFERROR(E5,"#N/C"), _xlpm.fam,IFERROR(F5,"#N/C"), _xlpm.subfam,IF(TRIM(G5)="-","#N/C",IFERROR(G5,"#N/C")), _xlpm.subfamMatch,IFERROR(_xlfn._xlws.FILTER(ClassificationClasses[Classification Class],(ClassificationClasses[Class]=_xlpm.cls)*(ClassificationClasses[Order]=_xlpm.ord)*(ClassificationClasses[Suborder]=_xlpm.subord)*(ClassificationClasses[Infraorder]=_xlpm.infr)*(ClassificationClasses[Superfamily]=_xlpm.sf)*(ClassificationClasses[Family]=_xlpm.fam)*(ClassificationClasses[Subfamily]=_xlpm.subfam),""),""), _xlpm.uniqueSubfam,IF(_xlpm.subfamMatch="","",_xlfn.UNIQUE(_xlpm.subfamMatch)), _xlpm.numUniqueSubfam,IF(_xlpm.uniqueSubfam="",0,ROWS(_xlpm.uniqueSubfam)), _xlpm.resultSubfam,IF(_xlpm.numUniqueSubfam=1,INDEX(_xlpm.uniqueSubfam,1),IF(_xlpm.numUniqueSubfam>=1,_xlpm.subfam,"")), _xlpm.famMatch,IFERROR(_xlfn._xlws.FILTER(ClassificationClasses[Classification Class],(ClassificationClasses[Class]=_xlpm.cls)*(ClassificationClasses[Order]=_xlpm.ord)*(ClassificationClasses[Suborder]=_xlpm.subord)*(ClassificationClasses[Infraorder]=_xlpm.infr)*(ClassificationClasses[Superfamily]=_xlpm.sf)*(ClassificationClasses[Family]=_xlpm.fam),""),""), _xlpm.uniqueFam,IF(_xlpm.famMatch="","",_xlfn.UNIQUE(_xlpm.famMatch)), _xlpm.numUniqueFam,IF(_xlpm.uniqueFam="",0,ROWS(_xlpm.uniqueFam)), _xlpm.resultFam,IF(_xlpm.numUniqueFam=1,INDEX(_xlpm.uniqueFam,1),IF(_xlpm.numUniqueFam>=1,_xlpm.fam,"")), _xlpm.sfMatch,IFERROR(_xlfn._xlws.FILTER(ClassificationClasses[Classification Class],(ClassificationClasses[Class]=_xlpm.cls)*(ClassificationClasses[Order]=_xlpm.ord)*(ClassificationClasses[Suborder]=_xlpm.subord)*(ClassificationClasses[Infraorder]=_xlpm.infr)*(ClassificationClasses[Superfamily]=_xlpm.sf),""),""), _xlpm.uniqueSf,IF(_xlpm.sfMatch="","",_xlfn.UNIQUE(_xlpm.sfMatch)), _xlpm.numUniqueSf,IF(_xlpm.uniqueSf="",0,ROWS(_xlpm.uniqueSf)), _xlpm.resultSf,IF(_xlpm.numUniqueSf=1,INDEX(_xlpm.uniqueSf,1),IF(_xlpm.numUniqueSf>=1,_xlpm.sf,"")), _xlpm.computedResult,IF(AND(_xlpm.fam="#N/C",_xlpm.subfam="#N/C"),_xlpm.sf,IF(_xlpm.resultSubfam<>"",_xlpm.resultSubfam,IF(_xlpm.resultFam<>"",_xlpm.resultFam,IF(_xlpm.resultSf<>"",_xlpm.resultSf,"")))), _xlpm.fallback,IF(IFERROR(B5,"#N/C")="#N/C",A5,IF(IFERROR(C5,"#N/C")="#N/C",B5,IF(IFERROR(D5,"#N/C")="#N/C",C5,IF(IFERROR(E5,"#N/C")="#N/C",D5,IF(IFERROR(F5,"#N/C")="#N/C",E5,IF(IFERROR(G5,"#N/C")="#N/C",F5,"#N/C")))))), _xlpm.finalResult,IF(OR(_xlpm.computedResult="",_xlpm.computedResult="#N/C"),_xlpm.fallback,_xlpm.computedResult), INDEX(_xlpm.finalResult,1))} -> spider | K5: =+CONCATENATE(A5,".",B5,".",C5,".",D5,".",E5,".",F5,".",G5,".",H5,".",I5) -> Arachnida.Araneae.Arneomorphae.Araneomorphae.Araneoidea.Araneidae.Araneinae.Araneus.#N/C | L5: =+COUNTIF([1]Monitoring!AN:AN,K5) -> 1
A6: Arachnida | B6: Araneae | C6: Arneomorphae | D6: =+IFERROR(IF(E6="#N/C","#N/C",INDEX([1]ClassificationClasses!D:D,MATCH(E6,[1]ClassificationClasses!E:E,0))),"ERROR") -> Araneomorphae | E6: Dictynoidea | F6: Anyphaenidae | G6: Anyphaeninae | H6: Anyphaena | I6: #N/C | J6: {=_xlfn.LET(_xlpm.cls,A6, _xlpm.ord,IFERROR(B6,"#N/C"), _xlpm.subord,IFERROR(C6,"#N/C"), _xlpm.infr,IFERROR(D6,"#N/C"), _xlpm.sf,IFERROR(E6,"#N/C"), _xlpm.fam,IFERROR(F6,"#N/C"), _xlpm.subfam,IF(TRIM(G6)="-","#N/C",IFERROR(G6,"#N/C")), _xlpm.subfamMatch,IFERROR(_xlfn._xlws.FILTER(ClassificationClasses[Classification Class],(ClassificationClasses[Class]=_xlpm.cls)*(ClassificationClasses[Order]=_xlpm.ord)*(ClassificationClasses[Suborder]=_xlpm.subord)*(ClassificationClasses[Infraorder]=_xlpm.infr)*(ClassificationClasses[Superfamily]=_xlpm.sf)*(ClassificationClasses[Family]=_xlpm.fam)*(ClassificationClasses[Subfamily]=_xlpm.subfam),""),""), _xlpm.uniqueSubfam,IF(_xlpm.subfamMatch="","",_xlfn.UNIQUE(_xlpm.subfamMatch)), _xlpm.numUniqueSubfam,IF(_xlpm.uniqueSubfam="",0,ROWS(_xlpm.uniqueSubfam)), _xlpm.resultSubfam,IF(_xlpm.numUniqueSubfam=1,INDEX(_xlpm.uniqueSubfam,1),IF(_xlpm.numUniqueSubfam>=1,_xlpm.subfam,"")), _xlpm.famMatch,IFERROR(_xlfn._xlws.FILTER(ClassificationClasses[Classification Class],(ClassificationClasses[Class]=_xlpm.cls)*(ClassificationClasses[Order]=_xlpm.ord)*(ClassificationClasses[Suborder]=_xlpm.subord)*(ClassificationClasses[Infraorder]=_xlpm.infr)*(ClassificationClasses[Superfamily]=_xlpm.sf)*(ClassificationClasses[Family]=_xlpm.fam),""),""), _xlpm.uniqueFam,IF(_xlpm.famMatch="","",_xlfn.UNIQUE(_xlpm.famMatch)), _xlpm.numUniqueFam,IF(_xlpm.uniqueFam="",0,ROWS(_xlpm.uniqueFam)), _xlpm.resultFam,IF(_xlpm.numUniqueFam=1,INDEX(_xlpm.uniqueFam,1),IF(_xlpm.numUniqueFam>=1,_xlpm.fam,"")), _xlpm.sfMatch,IFERROR(_xlfn._xlws.FILTER(ClassificationClasses[Classification Class],(ClassificationClasses[Class]=_xlpm.cls)*(ClassificationClasses[Order]=_xlpm.ord)*(ClassificationClasses[Suborder]=_xlpm.subord)*(ClassificationClasses[Infraorder]=_xlpm.infr)*(ClassificationClasses[Superfamily]=_xlpm.sf),""),""), _xlpm.uniqueSf,IF(_xlpm.sfMatch="","",_xlfn.UNIQUE(_xlpm.sfMatch)), _xlpm.numUniqueSf,IF(_xlpm.uniqueSf="",0,ROWS(_xlpm.uniqueSf)), _xlpm.resultSf,IF(_xlpm.numUniqueSf=1,INDEX(_xlpm.uniqueSf,1),IF(_xlpm.numUniqueSf>=1,_xlpm.sf,"")), _xlpm.computedResult,IF(AND(_xlpm.fam="#N/C",_xlpm.subfam="#N/C"),_xlpm.sf,IF(_xlpm.resultSubfam<>"",_xlpm.resultSubfam,IF(_xlpm.resultFam<>"",_xlpm.resultFam,IF(_xlpm.resultSf<>"",_xlpm.resultSf,"")))), _xlpm.fallback,IF(IFERROR(B6,"#N/C")="#N/C",A6,IF(IFERROR(C6,"#N/C")="#N/C",B6,IF(IFERROR(D6,"#N/C")="#N/C",C6,IF(IFERROR(E6,"#N/C")="#N/C",D6,IF(IFERROR(F6,"#N/C")="#N/C",E6,IF(IFERROR(G6,"#N/C")="#N/C",F6,"#N/C")))))), _xlpm.finalResult,IF(OR(_xlpm.computedResult="",_xlpm.computedResult="#N/C"),_xlpm.fallback,_xlpm.computedResult), INDEX(_xlpm.finalResult,1))} -> spider | K6: =+CONCATENATE(A6,".",B6,".",C6,".",D6,".",E6,".",F6,".",G6,".",H6,".",I6) -> Arachnida.Araneae.Arneomorphae.Araneomorphae.Dictynoidea.Anyphaenidae.Anyphaeninae.Anyphaena.#N/C | L6: =+COUNTIF([1]Monitoring!AN:AN,K6) -> 1
A7: Insecta | B7: #N/C | C7: #N/C | D7: =+IFERROR(IF(E7="#N/C","#N/C",INDEX([1]ClassificationClasses!D:D,MATCH(E7,[1]ClassificationClasses!E:E,0))),"ERROR") -> #N/C | E7: #N/C | F7: #N/C | G7: #N/C | H7: #N/C | I7: #N/C | J7: {=_xlfn.LET(_xlpm.cls,A7, _xlpm.ord,IFERROR(B7,"#N/C"), _xlpm.subord,IFERROR(C7,"#N/C"), _xlpm.infr,IFERROR(D7,"#N/C"), _xlpm.sf,IFERROR(E7,"#N/C"), _xlpm.fam,IFERROR(F7,"#N/C"), _xlpm.subfam,IF(TRIM(G7)="-","#N/C",IFERROR(G7,"#N/C")), _xlpm.subfamMatch,IFERROR(_xlfn._xlws.FILTER(ClassificationClasses[Classification Class],(ClassificationClasses[Class]=_xlpm.cls)*(ClassificationClasses[Order]=_xlpm.ord)*(ClassificationClasses[Suborder]=_xlpm.subord)*(ClassificationClasses[Infraorder]=_xlpm.infr)*(ClassificationClasses[Superfamily]=_xlpm.sf)*(ClassificationClasses[Family]=_xlpm.fam)*(ClassificationClasses[Subfamily]=_xlpm.subfam),""),""), _xlpm.uniqueSubfam,IF(_xlpm.subfamMatch="","",_xlfn.UNIQUE(_xlpm.subfamMatch)), _xlpm.numUniqueSubfam,IF(_xlpm.uniqueSubfam="",0,ROWS(_xlpm.uniqueSubfam)), _xlpm.resultSubfam,IF(_xlpm.numUniqueSubfam=1,INDEX(_xlpm.uniqueSubfam,1),IF(_xlpm.numUniqueSubfam>=1,_xlpm.subfam,"")), _xlpm.famMatch,IFERROR(_xlfn._xlws.FILTER(ClassificationClasses[Classification Class],(ClassificationClasses[Class]=_xlpm.cls)*(ClassificationClasses[Order]=_xlpm.ord)*(ClassificationClasses[Suborder]=_xlpm.subord)*(ClassificationClasses[Infraorder]=_xlpm.infr)*(ClassificationClasses[Superfamily]=_xlpm.sf)*(ClassificationClasses[Family]=_xlpm.fam),""),""), _xlpm.uniqueFam,IF(_xlpm.famMatch="","",_xlfn.UNIQUE(_xlpm.famMatch)), _xlpm.numUniqueFam,IF(_xlpm.uniqueFam="",0,ROWS(_xlpm.uniqueFam)), _xlpm.resultFam,IF(_xlpm.numUniqueFam=1,INDEX(_xlpm.uniqueFam,1),IF(_xlpm.numUniqueFam>=1,_xlpm.fam,"")), _xlpm.sfMatch,IFERROR(_xlfn._xlws.FILTER(ClassificationClasses[Classification Class],(ClassificationClasses[Class]=_xlpm.cls)*(ClassificationClasses[Order]=_xlpm.ord)*(ClassificationClasses[Suborder]=_xlpm.subord)*(ClassificationClasses[Infraorder]=_xlpm.infr)*(ClassificationClasses[Superfamily]=_xlpm.sf),""),""), _xlpm.uniqueSf,IF(_xlpm.sfMatch="","",_xlfn.UNIQUE(_xlpm.sfMatch)), _xlpm.numUniqueSf,IF(_xlpm.uniqueSf="",0,ROWS(_xlpm.uniqueSf)), _xlpm.resultSf,IF(_xlpm.numUniqueSf=1,INDEX(_xlpm.uniqueSf,1),IF(_xlpm.numUniqueSf>=1,_xlpm.sf,"")), _xlpm.computedResult,IF(AND(_xlpm.fam="#N/C",_xlpm.subfam="#N/C"),_xlpm.sf,IF(_xlpm.resultSubfam<>"",_xlpm.resultSubfam,IF(_xlpm.resultFam<>"",_xlpm.resultFam,IF(_xlpm.resultSf<>"",_xlpm.resultSf,"")))), _xlpm.fallback,IF(IFERROR(B7,"#N/C")="#N/C",A7,IF(IFERROR(C7,"#N/C")="#N/C",B7,IF(IFERROR(D7,"#N/C")="#N/C",C7,IF(IFERROR(E7,"#N/C")="#N/C",D7,IF(IFERROR(F7,"#N/C")="#N/C",E7,IF(IFERROR(G7,"#N/C")="#N/C",F7,"#N/C")))))), _xlpm.finalResult,IF(OR(_xlpm.computedResult="",_xlpm.computedResult="#N/C"),_xlpm.fallback,_xlpm.computedResult), INDEX(_xlpm.finalResult,1))} -> Insecta | K7: =+CONCATENATE(A7,".",B7,".",C7,".",D7,".",E7,".",F7,".",G7,".",H7,".",I7) -> Insecta.#N/C.#N/C.#N/C.#N/C.#N/C.#N/C.#N/C.#N/C | L7: =+COUNTIF([1]Monitoring!AN:AN,K7) -> 26
A8: Insecta | B8: Coleoptera | C8: Polyphaga | D8: =+IFERROR(IF(E8="#N/C","#N/C",INDEX([1]ClassificationClasses!D:D,MATCH(E8,[1]ClassificationClasses!E:E,0))),"ERROR") -> Cucujiformia | E8: Chrysomeloidea | F8: Chrysomelidae | G8: Alticinae | H8: #N/C | I8: #N/C | J8: {=_xlfn.LET(_xlpm.cls,A8, _xlpm.ord,IFERROR(B8,"#N/C"), _xlpm.subord,IFERROR(C8,"#N/C"), _xlpm.infr,IFERROR(D8,"#N/C"), _xlpm.sf,IFERROR(E8,"#N/C"), _xlpm.fam,IFERROR(F8,"#N/C"), _xlpm.subfam,IF(TRIM(G8)="-","#N/C",IFERROR(G8,"#N/C")), _xlpm.subfamMatch,IFERROR(_xlfn._xlws.FILTER(ClassificationClasses[Classification Class],(ClassificationClasses[Class]=_xlpm.cls)*(ClassificationClasses[Order]=_xlpm.ord)*(ClassificationClasses[Suborder]=_xlpm.subord)*(ClassificationClasses[Infraorder]=_xlpm.infr)*(ClassificationClasses[Superfamily]=_xlpm.sf)*(ClassificationClasses[Family]=_xlpm.fam)*(ClassificationClasses[Subfamily]=_xlpm.subfam),""),""), _xlpm.uniqueSubfam,IF(_xlpm.subfamMatch="","",_xlfn.UNIQUE(_xlpm.subfamMatch)), _xlpm.numUniqueSubfam,IF(_xlpm.uniqueSubfam="",0,ROWS(_xlpm.uniqueSubfam)), _xlpm.resultSubfam,IF(_xlpm.numUniqueSubfam=1,INDEX(_xlpm.uniqueSubfam,1),IF(_xlpm.numUniqueSubfam>=1,_xlpm.subfam,"")), _xlpm.famMatch,IFERROR(_xlfn._xlws.FILTER(ClassificationClasses[Classification Class],(ClassificationClasses[Class]=_xlpm.cls)*(ClassificationClasses[Order]=_xlpm.ord)*(ClassificationClasses[Suborder]=_xlpm.subord)*(ClassificationClasses[Infraorder]=_xlpm.infr)*(ClassificationClasses[Superfamily]=_xlpm.sf)*(ClassificationClasses[Family]=_xlpm.fam),""),""), _xlpm.uniqueFam,IF(_xlpm.famMatch="","",_xlfn.UNIQUE(_xlpm.famMatch)), _xlpm.numUniqueFam,IF(_xlpm.uniqueFam="",0,ROWS(_xlpm.uniqueFam)), _xlpm.resultFam,IF(_xlpm.numUniqueFam=1,INDEX(_xlpm.uniqueFam,1),IF(_xlpm.numUniqueFam>=1,_xlpm.fam,"")), _xlpm.sfMatch,IFERROR(_xlfn._xlws.FILTER(ClassificationClasses[Classification Class],(ClassificationClasses[Class]=_xlpm.cls)*(ClassificationClasses[Order]=_xlpm.ord)*(ClassificationClasses[Suborder]=_xlpm.subord)*(ClassificationClasses[Infraorder]=_xlpm.infr)*(ClassificationClasses[Superfamily]=_xlpm.sf),""),""), _xlpm.uniqueSf,IF(_xlpm.sfMatch="","",_xlfn.UNIQUE(_xlpm.sfMatch)), _xlpm.numUniqueSf,IF(_xlpm.uniqueSf="",0,ROWS(_xlpm.uniqueSf)), _xlpm.resultSf,IF(_xlpm.numUniqueSf=1,INDEX(_xlpm.uniqueSf,1),IF(_xlpm.numUniqueSf>=1,_xlpm.sf,"")), _xlpm.computedResult,IF(AND(_xlpm.fam="#N/C",_xlpm.subfam="#N/C"),_xlpm.sf,IF(_xlpm.resultSubfam<>"",_xlpm.resultSubfam,IF(_xlpm.resultFam<>"",_xlpm.resultFam,IF(_xlpm.resultSf<>"",_xlpm.resultSf,"")))), _xlpm.fallback,IF(IFERROR(B8,"#N/C")="#N/C",A8,IF(IFERROR(C8,"#N/C")="#N/C",B8,IF(IFERROR(D8,"#N/C")="#N/C",C8,IF(IFERROR(E8,"#N/C")="#N/C",D8,IF(IFERROR(F8,"#N/C")="#N/C",E8,IF(IFERROR(G8,"#N/C")="#N/C",F8,"#N/C")))))), _xlpm.finalResult,IF(OR(_xlpm.computedResult="",_xlpm.computedResult="#N/C"),_xlpm.fallback,_xlpm.computedResult), INDEX(_xlpm.finalResult,1))} -> leaf_beetle | K8: =+CONCATENATE(A8,".",B8,".",C8,".",D8,".",E8,".",F8,".",G8,".",H8,".",I8) -> Insecta.Coleoptera.Polyphaga.Cucujiformia.Chrysomeloidea.Chrysomelidae.Alticinae.#N/C.#N/C | L8: =+COUNTIF([1]Monitoring!AN:AN,K8) -> 1
A9: Insecta | B9: Coleoptera | C9: Polyphaga | D9: =+IFERROR(IF(E9="#N/C","#N/C",INDEX([1]ClassificationClasses!D:D,MATCH(E9,[1]ClassificationClasses!E:E,0))),"ERROR") -> Cucujiformia | E9: Chrysomeloidea | F9: Chrysomelidae | G9: Chrysomelinae | H9: #N/C | I9: #N/C | J9: {=_xlfn.LET(_xlpm.cls,A9, _xlpm.ord,IFERROR(B9,"#N/C"), _xlpm.subord,IFERROR(C9,"#N/C"), _xlpm.infr,IFERROR(D9,"#N/C"), _xlpm.sf,IFERROR(E9,"#N/C"), _xlpm.fam,IFERROR(F9,"#N/C"), _xlpm.subfam,IF(TRIM(G9)="-","#N/C",IFERROR(G9,"#N/C")), _xlpm.subfamMatch,IFERROR(_xlfn._xlws.FILTER(ClassificationClasses[Classification Class],(ClassificationClasses[Class]=_xlpm.cls)*(ClassificationClasses[Order]=_xlpm.ord)*(ClassificationClasses[Suborder]=_xlpm.subord)*(ClassificationClasses[Infraorder]=_xlpm.infr)*(ClassificationClasses[Superfamily]=_xlpm.sf)*(ClassificationClasses[Family]=_xlpm.fam)*(ClassificationClasses[Subfamily]=_xlpm.subfam),""),""), _xlpm.uniqueSubfam,IF(_xlpm.subfamMatch="","",_xlfn.UNIQUE(_xlpm.subfamMatch)), _xlpm.numUniqueSubfam,IF(_xlpm.uniqueSubfam="",0,ROWS(_xlpm.uniqueSubfam)), _xlpm.resultSubfam,IF(_xlpm.numUniqueSubfam=1,INDEX(_xlpm.uniqueSubfam,1),IF(_xlpm.numUniqueSubfam>=1,_xlpm.subfam,"")), _xlpm.famMatch,IFERROR(_xlfn._xlws.FILTER(ClassificationClasses[Classification Class],(ClassificationClasses[Class]=_xlpm.cls)*(ClassificationClasses[Order]=_xlpm.ord)*(ClassificationClasses[Suborder]=_xlpm.subord)*(ClassificationClasses[Infraorder]=_xlpm.infr)*(ClassificationClasses[Superfamily]=_xlpm.sf)*(ClassificationClasses[Family]=_xlpm.fam),""),""), _xlpm.uniqueFam,IF(_xlpm.famMatch="","",_xlfn.UNIQUE(_xlpm.famMatch)), _xlpm.numUniqueFam,IF(_xlpm.uniqueFam="",0,ROWS(_xlpm.uniqueFam)), _xlpm.resultFam,IF(_xlpm.numUniqueFam=1,INDEX(_xlpm.uniqueFam,1),IF(_xlpm.numUniqueFam>=1,_xlpm.fam,"")), _xlpm.sfMatch,IFERROR(_xlfn._xlws.FILTER(ClassificationClasses[Classification Class],(ClassificationClasses[Class]=_xlpm.cls)*(ClassificationClasses[Order]=_xlpm.ord)*(ClassificationClasses[Suborder]=_xlpm.subord)*(ClassificationClasses[Infraorder]=_xlpm.infr)*(ClassificationClasses[Superfamily]=_xlpm.sf),""),""), _xlpm.uniqueSf,IF(_xlpm.sfMatch="","",_xlfn.UNIQUE(_xlpm.sfMatch)), _xlpm.numUniqueSf,IF(_xlpm.uniqueSf="",0,ROWS(_xlpm.uniqueSf)), _xlpm.resultSf,IF(_xlpm.numUniqueSf=1,INDEX(_xlpm.uniqueSf,1),IF(_xlpm.numUniqueSf>=1,_xlpm.sf,"")), _xlpm.computedResult,IF(AND(_xlpm.fam="#N/C",_xlpm.subfam="#N/C"),_xlpm.sf,IF(_xlpm.resultSubfam<>"",_xlpm.resultSubfam,IF(_xlpm.resultFam<>"",_xlpm.resultFam,IF(_xlpm.resultSf<>"",_xlpm.resultSf,"")))), _xlpm.fallback,IF(IFERROR(B9,"#N/C")="#N/C",A9,IF(IFERROR(C9,"#N/C")="#N/C",B9,IF(IFERROR(D9,"#N/C")="#N/C",C9,IF(IFERROR(E9,"#N/C")="#N/C",D9,IF(IFERROR(F9,"#N/C")="#N/C",E9,IF(IFERROR(G9,"#N/C")="#N/C",F9,"#N/C")))))), _xlpm.finalResult,IF(OR(_xlpm.computedResult="",_xlpm.computedResult="#N/C"),_xlpm.fallback,_xlpm.computedResult), INDEX(_xlpm.finalResult,1))} -> leaf_beetle | K9: =+CONCATENATE(A9,".",B9,".",C9,".",D9,".",E9,".",F9,".",G9,".",H9,".",I9) -> Insecta.Coleoptera.Polyphaga.Cucujiformia.Chrysomeloidea.Chrysomelidae.Chrysomelinae.#N/C.#N/C | L9: =+COUNTIF([1]Monitoring!AN:AN,K9) -> 0
A10: Insecta | B10: Coleoptera | C10: Polyphaga | D10: =+IFERROR(IF(E10="#N/C","#N/C",INDEX([1]ClassificationClasses!D:D,MATCH(E10,[1]ClassificationClasses!E:E,0))),"ERROR") -> Cucujiformia | E10: Chrysomeloidea | F10: Chrysomelidae | G10: Chrysomelinae | H10: Chrysolina | I10: #N/C | J10: {=_xlfn.LET(_xlpm.cls,A10, _xlpm.ord,IFERROR(B10,"#N/C"), _xlpm.subord,IFERROR(C10,"#N/C"), _xlpm.infr,IFERROR(D10,"#N/C"), _xlpm.sf,IFERROR(E10,"#N/C"), _xlpm.fam,IFERROR(F10,"#N/C"), _xlpm.subfam,IF(TRIM(G10)="-","#N/C",IFERROR(G10,"#N/C")), _xlpm.subfamMatch,IFERROR(_xlfn._xlws.FILTER(ClassificationClasses[Classification Class],(ClassificationClasses[Class]=_xlpm.cls)*(ClassificationClasses[Order]=_xlpm.ord)*(ClassificationClasses[Suborder]=_xlpm.subord)*(ClassificationClasses[Infraorder]=_xlpm.infr)*(ClassificationClasses[Superfamily]=_xlpm.sf)*(ClassificationClasses[Family]=_xlpm.fam)*(ClassificationClasses[Subfamily]=_xlpm.subfam),""),""), _xlpm.uniqueSubfam,IF(_xlpm.subfamMatch="","",_xlfn.UNIQUE(_xlpm.subfamMatch)), _xlpm.numUniqueSubfam,IF(_xlpm.uniqueSubfam="",0,ROWS(_xlpm.uniqueSubfam)), _xlpm.resultSubfam,IF(_xlpm.numUniqueSubfam=1,INDEX(_xlpm.uniqueSubfam,1),IF(_xlpm.numUniqueSubfam>=1,_xlpm.subfam,"")), _xlpm.famMatch,IFERROR(_xlfn._xlws.FILTER(ClassificationClasses[Classification Class],(ClassificationClasses[Class]=_xlpm.cls)*(ClassificationClasses[Order]=_xlpm.ord)*(ClassificationClasses[Suborder]=_xlpm.subord)*(ClassificationClasses[Infraorder]=_xlpm.infr)*(ClassificationClasses[Superfamily]=_xlpm.sf)*(ClassificationClasses[Family]=_xlpm.fam),""),""), _xlpm.uniqueFam,IF(_xlpm.famMatch="","",_xlfn.UNIQUE(_xlpm.famMatch)), _xlpm.numUniqueFam,IF(_xlpm.uniqueFam="",0,ROWS(_xlpm.uniqueFam)), _xlpm.resultFam,IF(_xlpm.numUniqueFam=1,INDEX(_xlpm.uniqueFam,1),IF(_xlpm.numUniqueFam>=1,_xlpm.fam,"")), _xlpm.sfMatch,IFERROR(_xlfn._xlws.FILTER(ClassificationClasses[Classification Class],(ClassificationClasses[Class]=_xlpm.cls)*(ClassificationClasses[Order]=_xlpm.ord)*(ClassificationClasses[Suborder]=_xlpm.subord)*(ClassificationClasses[Infraorder]=_xlpm.infr)*(ClassificationClasses[Superfamily]=_xlpm.sf),""),""), _xlpm.uniqueSf,IF(_xlpm.sfMatch="","",_xlfn.UNIQUE(_xlpm.sfMatch)), _xlpm.numUniqueSf,IF(_xlpm.uniqueSf="",0,ROWS(_xlpm.uniqueSf)), _xlpm.resultSf,IF(_xlpm.numUniqueSf=1,INDEX(_xlpm.uniqueSf,1),IF(_xlpm.numUniqueSf>=1,_xlpm.sf,"")), _xlpm.computedResult,IF(AND(_xlpm.fam="#N/C",_xlpm.subfam="#N/C"),_xlpm.sf,IF(_xlpm.resultSubfam<>"",_xlpm.resultSubfam,IF(_xlpm.resultFam<>"",_xlpm.resultFam,IF(_xlpm.resultSf<>"",_xlpm.resultSf,"")))), _xlpm.fallback,IF(IFERROR(B10,"#N/C")="#N/C",A10,IF(IFERROR(C10,"#N/C")="#N/C",B10,IF(IFERROR(D10,"#N/C")="#N/C",C10,IF(IFERROR(E10,"#N/C")="#N/C",D10,IF(IFERROR(F10,"#N/C")="#N/C",E10,IF(IFERROR(G10,"#N/C")="#N/C",F10,"#N/C")))))), _xlpm.finalResult,IF(OR(_xlpm.computedResult="",_xlpm.computedResult="#N/C"),_xlpm.fallback,_xlpm.computedResult), INDEX(_xlpm.finalResult,1))} -> leaf_beetle | K10: =+CONCATENATE(A10,".",B10,".",C10,".",D10,".",E10,".",F10,".",G10,".",H10,".",I10) -> Insecta.Coleoptera.Polyphaga.Cucujiformia.Chrysomeloidea.Chrysomelidae.Chrysomelinae.Chrysolina.#N/C | L10: =+COUNTIF([1]Monitoring!AN:AN,K10) -> 0
